Workbook

Sheet Charts
A1: Regional Distribution of Sales by Product

Sheet Whisky Cask Sorted Sales
B1: Whisky Cask Sales Sorted by Area Per Region
B3: England | E3: Scotland | H3: Wales | K3: N.Ireland
B4: Area | C4: Sales | E4: Area | F4: Sales | H4: Area | I4: Sales | K4: Area | L4: Sales
B5: =Data!G52 -> NE | C5: =Data!I52 -> 3639.95 | E5: =Data!G14 -> EH | F5: =Data!I14 -> 5327.2 | H5: =Data!G25 -> NP | I5: =Data!I25 -> 2688 | K5: =Data!G16 -> BT | L5: =Data!I16 -> 694
B6: =Data!G39 -> SK | C6: =Data!I39 -> 2625.15 | E6: =Data!G8 -> AB | F6: =Data!I8 -> 2811.55 | H6: =Data!G13 -> CF | I6: =Data!I13 -> 1493.85
B7: =Data!G36 -> BH | C7: =Data!I36 -> 2497.2 | E7: =Data!G11 -> G | F7: =Data!I11 -> 2356.75 | H7: =Data!G51 -> LL | I7: =Data!I51 -> 804.4
B8: =Data!G32 -> BS | C8: =Data!I32 -> 2472 | E8: =Data!G19 -> IV | F8: =Data!I19 -> 2051.15 | H8: =Data!G22 -> SY | I8: =Data!I22 -> 404.8
B9: =Data!G18 -> NG | C9: =Data!I18 -> 1998.8 | E9: =Data!G34 -> ML | F9: =Data!I34 -> 1373.15 | H9: =Data!G101 -> SA | I9: =Data!I101 -> 309.2
B10: =Data!G63 -> DE | C10: =Data!I63 -> 1836 | E10: =Data!G27 -> PH | F10: =Data!I27 -> 1267.95
B11: =Data!G21 -> S | C11: =Data!I21 -> 1793.15 | E11: =Data!G85 -> DD | F11: =Data!I85 -> 1193.6
B12: =Data!G75 -> CT | C12: =Data!I75 -> 1706 | E12: =Data!G30 -> DG | F12: =Data!I30 -> 1182.7
B13: =Data!G48 -> LS | C13: =Data!I48 -> 1644 | E13: =Data!G26 -> KY | F13: =Data!I26 -> 1110.7
B14: =Data!G17 -> B | C14: =Data!I17 -> 1544.35 | E14: =Data!G29 -> FK | F14: =Data!I29 -> 974.7
B15: =Data!G100 -> RH | C15: =Data!I100 -> 1428.8 | E15: =Data!G6 -> TD | F15: =Data!I6 -> 857.6
B16: =Data!G65 -> SO | C16: =Data!I65 -> 1408.3 | E16: =Data!G50 -> PA | F16: =Data!I50 -> 801.95
B17: =Data!G35 -> RG | C17: =Data!I35 -> 1404.4 | E17: =Data!G4 -> KA | F17: =Data!I4 -> 433.2
B18: =Data!G66 -> ST | C18: =Data!I66 -> 1355.2 | E18: =Data!G116 -> HS | F18: =Data!I116 -> 192
B19: =Data!G3 -> PE | C19: =Data!I3 -> 1353.2 | E19: =Data!G71 -> ZE | F19: =Data!I71 -> 112
B20: =Data!G54 -> TN | C20: =Data!I54 -> 1260.8 | E20: =Data!G90 -> KW | F20: =Data!I90 -> 109.6
B21: =Data!G10 -> L | C21: =Data!I10 -> 1231.2
B22: =Data!G67 -> LE | C22: =Data!I67 -> 1229.95
B23: =Data!G95 -> DY | C23: =Data!I95 -> 1229.6
B24: =Data!G46 -> DN | C24: =Data!I46 -> 1214.4
B25: =Data!G74 -> CV | C25: =Data!I74 -> 1161.95
B26: =Data!G81 -> CO | C26: =Data!I81 -> 1132.35
B27: =Data!G72 -> NN | C27: =Data!I72 -> 1110.8
B28: =Data!G89 -> WV | C28: =Data!I89 -> 1074
B29: =Data!G99 -> HU | C29: =Data!I99 -> 1033.6
B30: =Data!G73 -> YO | C30: =Data!I73 -> 1026.4
B31: =Data!G37 -> BN | C31: =Data!I37 -> 1018
B32: =Data!G78 -> SN | C32: =Data!I78 -> 993.15
B33: =Data!G104 -> WF | C33: =Data!I104 -> 941.2
B34: =Data!G24 -> BA | C34: =Data!I24 -> 931.6
B35: =Data!G70 -> HP | C35: =Data!I70 -> 926
B36: =Data!G38 -> GL | C36: =Data!I38 -> 904
B37: =Data!G7 -> OX | C37: =Data!I7 -> 903.2
B38: =Data!G92 -> MK | C38: =Data!I92 -> 853.6
B39: =Data!G9 -> SE | C39: =Data!I9 -> 832
B40: =Data!G108 -> N | C40: =Data!I108 -> 817.6
B41: =Data!G86 -> CM | C41: =Data!I86 -> 814.4
...

Sheet Data
A1: =IF(COUNTIF($V$3:$Y$99, $B1)<>0, ROW($B1), 0) -> 1 | B1: PE
A2: =IF(COUNTIF($V$3:$Y$99, $B2)<>0, ROW($B2), 0) -> 0 | B2: Total # Sold | C2: 68 | F2: Index | G2: Area | H2: Location | I2: Whisky Cask | J2: Strawberry | K2: Ginger | L2: Elderflower | M2: Original | N2: Scottish Fruits | O2: Cloudy | P2: Traditional | Q2: Total | S2: =I2 -> Whisky Cask | V2: Scottish Postcode Area Codes | W2: English Postcode Area Codes | X2: N.Irish Postcode Area Codes | Y2: Welsh Postcode Area Codes
A3: =IF(COUNTIF($V$3:$Y$99, $B3)<>0, ROW($B3), 0) -> 0 | B3: Total Sales | C3: 3033.05 | F3: 1 | G3: {=INDIRECT("B"&$F3)} -> PE | H3: {=_xlfn.IFS(COUNTIF($V$3:$V$18, G3)<>0, "S", COUNTIF($W$3:$W$99, G3)<>0, "E", COUNTIF($X$3, G3)<>0, "I", COUNTIF($Y$3:$Y$8, G3)<>0, "W")} -> E | I3: =SUMIF(OFFSET(INDIRECT("B"&$F3), 4, 0):INDIRECT("B"&$F4), "*"&$I$2&"*", OFFSET(INDIRECT("C"&$F3), 4, 0):OFFSET(INDIRECT("C"&$F4), -1, 0)) -> 1353.2 | J3: =SUMIF(OFFSET(INDIRECT("B"&$F3), 4, 0):INDIRECT("B"&$F4), "*"&$J$2&"*", OFFSET(INDIRECT("C"&$F3), 4, 0):OFFSET(INDIRECT("C"&$F4), -1, 0)) -> 328.8 | K3: =SUMIF(OFFSET(INDIRECT("B"&$F3), 4, 0):INDIRECT("B"&$F4), "*"&$K$2&"*", OFFSET(INDIRECT("C"&$F3), 4, 0):OFFSET(INDIRECT("C"&$F4), -1, 0)) -> 76.8 | L3: =SUMIF(OFFSET(INDIRECT("B"&$F3), 4, 0):INDIRECT("B"&$F4), "*"&$L$2&"*", OFFSET(INDIRECT("C"&$F3), 4, 0):OFFSET(INDIRECT("C"&$F4), -1, 0)) -> 54.8 | M3: =SUMIF(OFFSET(INDIRECT("B"&$F3), 4, 0):INDIRECT("B"&$F4), "*"&$M$2&"*", OFFSET(INDIRECT("C"&$F3), 4, 0):OFFSET(INDIRECT("C"&$F4), -1, 0)) -> 318 | N3: =SUMIF(OFFSET(INDIRECT("B"&$F3), 4, 0):INDIRECT("B"&$F4), "*"&$N$2&"*", OFFSET(INDIRECT("C"&$F3), 4, 0):OFFSET(INDIRECT("C"&$F4), -1, 0)) -> 28.75 | O3: =SUMIF(OFFSET(INDIRECT("B"&$F3), 4, 0):INDIRECT("B"&$F4), "*"&$O$2&"*", OFFSET(INDIRECT("C"&$F3), 4, 0):OFFSET(INDIRECT("C"&$F4), -1, 0)) -> 40 | P3: =SUMIF(OFFSET(INDIRECT("B"&$F3), 4, 0):INDIRECT("B"&$F4), "*"&$P$2&"*", OFFSET(INDIRECT("C"&$F3), 4, 0):OFFSET(INDIRECT("C"&$F4), -1, 0)) -> 237.15 | Q3: =SUM($I3:$P3) -> 2437.5 | S3: Region | T3: Sales | V3: AB | W3: AL | X3: BT | Y3: CF
A4: =IF(COUNTIF($V$3:$Y$99, $B4)<>0, ROW($B4), 0) -> 0 | B4: Product Name | C4: Sales | D4: Quantity | F4: {=INDEX(A2:OFFSET(A2, 100, 0),MATCH(TRUE,INDEX(A2:A50<>0,),0))} -> 23 | G4: {=INDIRECT("B"&$F4)} -> KA | H4: {=_xlfn.IFS(COUNTIF($V$3:$V$18, G4)<>0, "S", COUNTIF($W$3:$W$99, G4)<>0, "E", COUNTIF($X$3, G4)<>0, "I", COUNTIF($Y$3:$Y$8, G4)<>0, "W")} -> S | I4: =SUMIF(OFFSET(INDIRECT("B"&$F4), 4, 0):INDIRECT("B"&$F5), "*"&$I$2&"*", OFFSET(INDIRECT("C"&$F4), 4, 0):OFFSET(INDIRECT("C"&$F5), -1, 0)) -> 433.2 | J4: =SUMIF(OFFSET(INDIRECT("B"&$F4), 4, 0):INDIRECT("B"&$F5), "*"&$J$2&"*", OFFSET(INDIRECT("C"&$F4), 4, 0):OFFSET(INDIRECT("C"&$F5), -1, 0)) -> 390.72 | K4: =SUMIF(OFFSET(INDIRECT("B"&$F4), 4, 0):INDIRECT("B"&$F5), "*"&$K$2&"*", OFFSET(INDIRECT("C"&$F4), 4, 0):OFFSET(INDIRECT("C"&$F5), -1, 0)) -> 157.2 | L4: =SUMIF(OFFSET(INDIRECT("B"&$F4), 4, 0):INDIRECT("B"&$F5), "*"&$L$2&"*", OFFSET(INDIRECT("C"&$F4), 4, 0):OFFSET(INDIRECT("C"&$F5), -1, 0)) -> 87.97 | M4: =SUMIF(OFFSET(INDIRECT("B"&$F4), 4, 0):INDIRECT("B"&$F5), "*"&$M$2&"*", OFFSET(INDIRECT("C"&$F4), 4, 0):OFFSET(INDIRECT("C"&$F5), -1, 0)) -> 372.8 | N4: =SUMIF(OFFSET(INDIRECT("B"&$F4), 4, 0):INDIRECT("B"&$F5), "*"&$N$2&"*", OFFSET(INDIRECT("C"&$F4), 4, 0):OFFSET(INDIRECT("C"&$F5), -1, 0)) -> 260.92 | O4: =SUMIF(OFFSET(INDIRECT("B"&$F4), 4, 0):INDIRECT("B"&$F5), "*"&$O$2&"*", OFFSET(INDIRECT("C"&$F4), 4, 0):OFFSET(INDIRECT("C"&$F5), -1, 0)) -> 230.4 | P4: =SUMIF(OFFSET(INDIRECT("B"&$F4), 4, 0):INDIRECT("B"&$F5), "*"&$P$2&"*", OFFSET(INDIRECT("C"&$F4), 4, 0):OFFSET(INDIRECT("C"&$F5), -1, 0)) -> 833.9 | Q4: =SUM($I4:$P4) -> 2767.11 | S4: England | T4: =SUMIF($H$3:$H$120, "E", $I$3:$I$120) -> 77607.81 | V4: DD | W4: B | Y4: LD
A5: =IF(COUNTIF($V$3:$Y$99, $B5)<>0, ROW($B5), 0) -> 0 | B5: Original - Bottle 24 x 500ml | C5: 164.4 | D5: 6 | F5: {=INDEX(OFFSET(INDIRECT("A"&F4), 1, 0):OFFSET(OFFSET(INDIRECT("A"&F4), 1, 0), 100, 0),MATCH(TRUE,INDEX(OFFSET(INDIRECT("A"&F4), 1, 0):OFFSET(OFFSET(INDIRECT("A"&F4), 1, 0), 100, 0)<>0,),0))} -> 60 | G5: {=INDIRECT("B"&$F5)} -> EC | H5: {=_xlfn.IFS(COUNTIF($V$3:$V$18, G5)<>0, "S", COUNTIF($W$3:$W$99, G5)<>0, "E", COUNTIF($X$3, G5)<>0, "I", COUNTIF($Y$3:$Y$8, G5)<>0, "W")} -> E | I5: =SUMIF(OFFSET(INDIRECT("B"&$F5), 4, 0):INDIRECT("B"&$F6), "*"&$I$2&"*", OFFSET(INDIRECT("C"&$F5), 4, 0):OFFSET(INDIRECT("C"&$F6), -1, 0)) -> 93.2 | J5: =SUMIF(OFFSET(INDIRECT("B"&$F5), 4, 0):INDIRECT("B"&$F6), "*"&$J$2&"*", OFFSET(INDIRECT("C"&$F5), 4, 0):OFFSET(INDIRECT("C"&$F6), -1, 0)) -> 0 | K5: =SUMIF(OFFSET(INDIRECT("B"&$F5), 4, 0):INDIRECT("B"&$F6), "*"&$K$2&"*", OFFSET(INDIRECT("C"&$F5), 4, 0):OFFSET(INDIRECT("C"&$F6), -1, 0)) -> 38.4 | L5: =SUMIF(OFFSET(INDIRECT("B"&$F5), 4, 0):INDIRECT("B"&$F6), "*"&$L$2&"*", OFFSET(INDIRECT("C"&$F5), 4, 0):OFFSET(INDIRECT("C"&$F6), -1, 0)) -> 341.6 | M5: =SUMIF(OFFSET(INDIRECT("B"&$F5), 4, 0):INDIRECT("B"&$F6), "*"&$M$2&"*", OFFSET(INDIRECT("C"&$F5), 4, 0):OFFSET(INDIRECT("C"&$F6), -1, 0)) -> 0 | N5: =SUMIF(OFFSET(INDIRECT("B"&$F5), 4, 0):INDIRECT("B"&$F6), "*"&$N$2&"*", OFFSET(INDIRECT("C"&$F5), 4, 0):OFFSET(INDIRECT("C"&$F6), -1, 0)) -> 0 | O5: =SUMIF(OFFSET(INDIRECT("B"&$F5), 4, 0):INDIRECT("B"&$F6), "*"&$O$2&"*", OFFSET(INDIRECT("C"&$F5), 4, 0):OFFSET(INDIRECT("C"&$F6), -1, 0)) -> 0 | P5: =SUMIF(OFFSET(INDIRECT("B"&$F5), 4, 0):INDIRECT("B"&$F6), "*"&$P$2&"*", OFFSET(INDIRECT("C"&$F5), 4, 0):OFFSET(INDIRECT("C"&$F6), -1, 0)) -> 54.8 | Q5: =SUM($I5:$P5) -> 528 | S5: Scotland | T5: =SUMIF($H$3:$H$120, "S", $I$3:$I$120) -> 22155.8 | V5: DG | W5: BA | Y5: LL
A6: =IF(COUNTIF($V$3:$Y$99, $B6)<>0, ROW($B6), 0) -> 0 | B6: Traditional - Bottle 24 x 500ml | C6: 54.8 | D6: 1 | F6: {=INDEX(OFFSET(INDIRECT("A"&F5), 1, 0):OFFSET(OFFSET(INDIRECT("A"&F5), 1, 0), 100, 0),MATCH(TRUE,INDEX(OFFSET(INDIRECT("A"&F5), 1, 0):OFFSET(OFFSET(INDIRECT("A"&F5), 1, 0), 100, 0)<>0,),0))} -> 73 | G6: {=INDIRECT("B"&$F6)} -> TD | H6: {=_xlfn.IFS(COUNTIF($V$3:$V$18, G6)<>0, "S", COUNTIF($W$3:$W$99, G6)<>0, "E", COUNTIF($X$3, G6)<>0, "I", COUNTIF($Y$3:$Y$8, G6)<>0, "W")} -> S | I6: =SUMIF(OFFSET(INDIRECT("B"&$F6), 4, 0):INDIRECT("B"&$F7), "*"&$I$2&"*", OFFSET(INDIRECT("C"&$F6), 4, 0):OFFSET(INDIRECT("C"&$F7), -1, 0)) -> 857.6 | J6: =SUMIF(OFFSET(INDIRECT("B"&$F6), 4, 0):INDIRECT("B"&$F7), "*"&$J$2&"*", OFFSET(INDIRECT("C"&$F6), 4, 0):OFFSET(INDIRECT("C"&$F7), -1, 0)) -> 237.36 | K6: =SUMIF(OFFSET(INDIRECT("B"&$F6), 4, 0):INDIRECT("B"&$F7), "*"&$K$2&"*", OFFSET(INDIRECT("C"&$F6), 4, 0):OFFSET(INDIRECT("C"&$F7), -1, 0)) -> 105.55 | L6: =SUMIF(OFFSET(INDIRECT("B"&$F6), 4, 0):INDIRECT("B"&$F7), "*"&$L$2&"*", OFFSET(INDIRECT("C"&$F6), 4, 0):OFFSET(INDIRECT("C"&$F7), -1, 0)) -> 174.1 | M6: =SUMIF(OFFSET(INDIRECT("B"&$F6), 4, 0):INDIRECT("B"&$F7), "*"&$M$2&"*", OFFSET(INDIRECT("C"&$F6), 4, 0):OFFSET(INDIRECT("C"&$F7), -1, 0)) -> 252 | N6: =SUMIF(OFFSET(INDIRECT("B"&$F6), 4, 0):INDIRECT("B"&$F7), "*"&$N$2&"*", OFFSET(INDIRECT("C"&$F6), 4, 0):OFFSET(INDIRECT("C"&$F7), -1, 0)) -> 232.17 | O6: =SUMIF(OFFSET(INDIRECT("B"&$F6), 4, 0):INDIRECT("B"&$F7), "*"&$O$2&"*", OFFSET(INDIRECT("C"&$F6), 4, 0):OFFSET(INDIRECT("C"&$F7), -1, 0)) -> 116.8 | P6: =SUMIF(OFFSET(INDIRECT("B"&$F6), 4, 0):INDIRECT("B"&$F7), "*"&$P$2&"*", OFFSET(INDIRECT("C"&$F6), 4, 0):OFFSET(INDIRECT("C"&$F7), -1, 0)) -> 855.4 | Q6: =SUM($I6:$P6) -> 2830.98 | S6: N.Ireland | T6: =SUMIF($H$3:$H$120, "I", $I$3:$I$120) -> 694 | V6: EH | W6: BB | Y6: NP
A7: =IF(COUNTIF($V$3:$Y$99, $B7)<>0, ROW($B7), 0) -> 0 | B7: Whisky Cask - Bottle 24 x 500ml | C7: 602.8 | D7: 11 | F7: {=INDEX(OFFSET(INDIRECT("A"&F6), 1, 0):OFFSET(OFFSET(INDIRECT("A"&F6), 1, 0), 100, 0),MATCH(TRUE,INDEX(OFFSET(INDIRECT("A"&F6), 1, 0):OFFSET(OFFSET(INDIRECT("A"&F6), 1, 0), 100, 0)<>0,),0))} -> 111 | G7: {=INDIRECT("B"&$F7)} -> OX | H7: {=_xlfn.IFS(COUNTIF($V$3:$V$18, G7)<>0, "S", COUNTIF($W$3:$W$99, G7)<>0, "E", COUNTIF($X$3, G7)<>0, "I", COUNTIF($Y$3:$Y$8, G7)<>0, "W")} -> E | I7: =SUMIF(OFFSET(INDIRECT("B"&$F7), 4, 0):INDIRECT("B"&$F8), "*"&$I$2&"*", OFFSET(INDIRECT("C"&$F7), 4, 0):OFFSET(INDIRECT("C"&$F8), -1, 0)) -> 903.2 | J7: =SUMIF(OFFSET(INDIRECT("B"&$F7), 4, 0):INDIRECT("B"&$F8), "*"&$J$2&"*", OFFSET(INDIRECT("C"&$F7), 4, 0):OFFSET(INDIRECT("C"&$F8), -1, 0)) -> 149.6 | K7: =SUMIF(OFFSET(INDIRECT("B"&$F7), 4, 0):INDIRECT("B"&$F8), "*"&$K$2&"*", OFFSET(INDIRECT("C"&$F7), 4, 0):OFFSET(INDIRECT("C"&$F8), -1, 0)) -> 76.8 | L7: =SUMIF(OFFSET(INDIRECT("B"&$F7), 4, 0):INDIRECT("B"&$F8), "*"&$L$2&"*", OFFSET(INDIRECT("C"&$F7), 4, 0):OFFSET(INDIRECT("C"&$F8), -1, 0)) -> 76.8 | M7: =SUMIF(OFFSET(INDIRECT("B"&$F7), 4, 0):INDIRECT("B"&$F8), "*"&$M$2&"*", OFFSET(INDIRECT("C"&$F7), 4, 0):OFFSET(INDIRECT("C"&$F8), -1, 0)) -> 40 | N7: =SUMIF(OFFSET(INDIRECT("B"&$F7), 4, 0):INDIRECT("B"&$F8), "*"&$N$2&"*", OFFSET(INDIRECT("C"&$F7), 4, 0):OFFSET(INDIRECT("C"&$F8), -1, 0)) -> 28.75 | O7: =SUMIF(OFFSET(INDIRECT("B"&$F7), 4, 0):INDIRECT("B"&$F8), "*"&$O$2&"*", OFFSET(INDIRECT("C"&$F7), 4, 0):OFFSET(INDIRECT("C"&$F8), -1, 0)) -> 38.4 | P7: =SUMIF(OFFSET(INDIRECT("B"&$F7), 4, 0):INDIRECT("B"&$F8), "*"&$P$2&"*", OFFSET(INDIRECT("C"&$F7), 4, 0):OFFSET(INDIRECT("C"&$F8), -1, 0)) -> 331.95 | Q7: =SUM($I7:$P7) -> 1645.5 | S7: Wales | T7: =SUMIF($H$3:$H$120, "W", $I$3:$I$120) -> 5700.25 | V7: FK | W7: BD | Y7: SA
A8: =IF(COUNTIF($V$3:$Y$99, $B8)<>0, ROW($B8), 0) -> 0 | B8: Strawberry - Bottle 24 x 500ml | C8: 328.8 | D8: 6 | F8: {=INDEX(OFFSET(INDIRECT("A"&F7), 1, 0):OFFSET(OFFSET(INDIRECT("A"&F7), 1, 0), 100, 0),MATCH(TRUE,INDEX(OFFSET(INDIRECT("A"&F7), 1, 0):OFFSET(OFFSET(INDIRECT("A"&F7), 1, 0), 100, 0)<>0,),0))} -> 135 | G8: {=INDIRECT("B"&$F8)} -> AB | H8: {=_xlfn.IFS(COUNTIF($V$3:$V$18, G8)<>0, "S", COUNTIF($W$3:$W$99, G8)<>0, "E", COUNTIF($X$3, G8)<>0, "I", COUNTIF($Y$3:$Y$8, G8)<>0, "W")} -> S | I8: =SUMIF(OFFSET(INDIRECT("B"&$F8), 4, 0):INDIRECT("B"&$F9), "*"&$I$2&"*", OFFSET(INDIRECT("C"&$F8), 4, 0):OFFSET(INDIRECT("C"&$F9), -1, 0)) -> 2811.55 | J8: =SUMIF(OFFSET(INDIRECT("B"&$F8), 4, 0):INDIRECT("B"&$F9), "*"&$J$2&"*", OFFSET(INDIRECT("C"&$F8), 4, 0):OFFSET(INDIRECT("C"&$F9), -1, 0)) -> 1175.05 | K8: =SUMIF(OFFSET(INDIRECT("B"&$F8), 4, 0):INDIRECT("B"&$F9), "*"&$K$2&"*", OFFSET(INDIRECT("C"&$F8), 4, 0):OFFSET(INDIRECT("C"&$F9), -1, 0)) -> 143.95 | L8: =SUMIF(OFFSET(INDIRECT("B"&$F8), 4, 0):INDIRECT("B"&$F9), "*"&$L$2&"*", OFFSET(INDIRECT("C"&$F8), 4, 0):OFFSET(INDIRECT("C"&$F9), -1, 0)) -> 1012.43 | M8: =SUMIF(OFFSET(INDIRECT("B"&$F8), 4, 0):INDIRECT("B"&$F9), "*"&$M$2&"*", OFFSET(INDIRECT("C"&$F8), 4, 0):OFFSET(INDIRECT("C"&$F9), -1, 0)) -> 1153.2 | N8: =SUMIF(OFFSET(INDIRECT("B"&$F8), 4, 0):INDIRECT("B"&$F9), "*"&$N$2&"*", OFFSET(INDIRECT("C"&$F8), 4, 0):OFFSET(INDIRECT("C"&$F9), -1, 0)) -> 819.19 | O8: =SUMIF(OFFSET(INDIRECT("B"&$F8), 4, 0):INDIRECT("B"&$F9), "*"&$O$2&"*", OFFSET(INDIRECT("C"&$F8), 4, 0):OFFSET(INDIRECT("C"&$F9), -1, 0)) -> 528 | P8: =SUMIF(OFFSET(INDIRECT("B"&$F8), 4, 0):INDIRECT("B"&$F9), "*"&$P$2&"*", OFFSET(INDIRECT("C"&$F8), 4, 0):OFFSET(INDIRECT("C"&$F9), -1, 0)) -> 3577.25 | Q8: =SUM($I8:$P8) -> 11220.62 | S8: Total | T8: =SUM(T4:T7) -> 106157.86 | V8: G | W8: BH | Y8: SY
A9: =IF(COUNTIF($V$3:$Y$99, $B9)<>0, ROW($B9), 0) -> 0 | B9: Ginger - Bottle 24 x 330ml | C9: 76.8 | D9: 2 | F9: {=INDEX(OFFSET(INDIRECT("A"&F8), 1, 0):OFFSET(OFFSET(INDIRECT("A"&F8), 1, 0), 100, 0),MATCH(TRUE,INDEX(OFFSET(INDIRECT("A"&F8), 1, 0):OFFSET(OFFSET(INDIRECT("A"&F8), 1, 0), 100, 0)<>0,),0))} -> 188 | G9: {=INDIRECT("B"&$F9)} -> SE | H9: {=_xlfn.IFS(COUNTIF($V$3:$V$18, G9)<>0, "S", COUNTIF($W$3:$W$99, G9)<>0, "E", COUNTIF($X$3, G9)<>0, "I", COUNTIF($Y$3:$Y$8, G9)<>0, "W")} -> E | I9: =SUMIF(OFFSET(INDIRECT("B"&$F9), 4, 0):INDIRECT("B"&$F10), "*"&$I$2&"*", OFFSET(INDIRECT("C"&$F9), 4, 0):OFFSET(INDIRECT("C"&$F10), -1, 0)) -> 832 | J9: =SUMIF(OFFSET(INDIRECT("B"&$F9), 4, 0):INDIRECT("B"&$F10), "*"&$J$2&"*", OFFSET(INDIRECT("C"&$F9), 4, 0):OFFSET(INDIRECT("C"&$F10), -1, 0)) -> 89.36 | K9: =SUMIF(OFFSET(INDIRECT("B"&$F9), 4, 0):INDIRECT("B"&$F10), "*"&$K$2&"*", OFFSET(INDIRECT("C"&$F9), 4, 0):OFFSET(INDIRECT("C"&$F10), -1, 0)) -> 40 | L9: =SUMIF(OFFSET(INDIRECT("B"&$F9), 4, 0):INDIRECT("B"&$F10), "*"&$L$2&"*", OFFSET(INDIRECT("C"&$F9), 4, 0):OFFSET(INDIRECT("C"&$F10), -1, 0)) -> 286.8 | M9: =SUMIF(OFFSET(INDIRECT("B"&$F9), 4, 0):INDIRECT("B"&$F10), "*"&$M$2&"*", OFFSET(INDIRECT("C"&$F9), 4, 0):OFFSET(INDIRECT("C"&$F10), -1, 0)) -> 38.4 | N9: =SUMIF(OFFSET(INDIRECT("B"&$F9), 4, 0):INDIRECT("B"&$F10), "*"&$N$2&"*", OFFSET(INDIRECT("C"&$F9), 4, 0):OFFSET(INDIRECT("C"&$F10), -1, 0)) -> 63.31 | O9: =SUMIF(OFFSET(INDIRECT("B"&$F9), 4, 0):INDIRECT("B"&$F10), "*"&$O$2&"*", OFFSET(INDIRECT("C"&$F9), 4, 0):OFFSET(INDIRECT("C"&$F10), -1, 0)) -> 0 | P9: =SUMIF(OFFSET(INDIRECT("B"&$F9), 4, 0):INDIRECT("B"&$F10), "*"&$P$2&"*", OFFSET(INDIRECT("C"&$F9), 4, 0):OFFSET(INDIRECT("C"&$F10), -1, 0)) -> 76.8 | Q9: =SUM($I9:$P9) -> 1426.67 | V9: HS | W9: BL
A10: =IF(COUNTIF($V$3:$Y$99, $B10)<>0, ROW($B10), 0) -> 0 | B10: Cloudy - 2x5L Ciderbox 2 x 5L Ciderbox | C10: 40 | D10: 1 | F10: {=INDEX(OFFSET(INDIRECT("A"&F9), 1, 0):OFFSET(OFFSET(INDIRECT("A"&F9), 1, 0), 100, 0),MATCH(TRUE,INDEX(OFFSET(INDIRECT("A"&F9), 1, 0):OFFSET(OFFSET(INDIRECT("A"&F9), 1, 0), 100, 0)<>0,),0))} -> 212 | G10: {=INDIRECT("B"&$F10)} -> L | H10: {=_xlfn.IFS(COUNTIF($V$3:$V$18, G10)<>0, "S", COUNTIF($W$3:$W$99, G10)<>0, "E", COUNTIF($X$3, G10)<>0, "I", COUNTIF($Y$3:$Y$8, G10)<>0, "W")} -> E | I10: =SUMIF(OFFSET(INDIRECT("B"&$F10), 4, 0):INDIRECT("B"&$F11), "*"&$I$2&"*", OFFSET(INDIRECT("C"&$F10), 4, 0):OFFSET(INDIRECT("C"&$F11), -1, 0)) -> 1231.2 | J10: =SUMIF(OFFSET(INDIRECT("B"&$F10), 4, 0):INDIRECT("B"&$F11), "*"&$J$2&"*", OFFSET(INDIRECT("C"&$F10), 4, 0):OFFSET(INDIRECT("C"&$F11), -1, 0)) -> 0 | K10: =SUMIF(OFFSET(INDIRECT("B"&$F10), 4, 0):INDIRECT("B"&$F11), "*"&$K$2&"*", OFFSET(INDIRECT("C"&$F10), 4, 0):OFFSET(INDIRECT("C"&$F11), -1, 0)) -> 0 | L10: =SUMIF(OFFSET(INDIRECT("B"&$F10), 4, 0):INDIRECT("B"&$F11), "*"&$L$2&"*", OFFSET(INDIRECT("C"&$F10), 4, 0):OFFSET(INDIRECT("C"&$F11), -1, 0)) -> 54.39 | M10: =SUMIF(OFFSET(INDIRECT("B"&$F10), 4, 0):INDIRECT("B"&$F11), "*"&$M$2&"*", OFFSET(INDIRECT("C"&$F10), 4, 0):OFFSET(INDIRECT("C"&$F11), -1, 0)) -> 40 | N10: =SUMIF(OFFSET(INDIRECT("B"&$F10), 4, 0):INDIRECT("B"&$F11), "*"&$N$2&"*", OFFSET(INDIRECT("C"&$F10), 4, 0):OFFSET(INDIRECT("C"&$F11), -1, 0)) -> 0 | O10: =SUMIF(OFFSET(INDIRECT("B"&$F10), 4, 0):INDIRECT("B"&$F11), "*"&$O$2&"*", OFFSET(INDIRECT("C"&$F10), 4, 0):OFFSET(INDIRECT("C"&$F11), -1, 0)) -> 0 | P10: =SUMIF(OFFSET(INDIRECT("B"&$F10), 4, 0):INDIRECT("B"&$F11), "*"&$P$2&"*", OFFSET(INDIRECT("C"&$F10), 4, 0):OFFSET(INDIRECT("C"&$F11), -1, 0)) -> 416.35 | Q10: =SUM($I10:$P10) -> 1741.94 | S10: =J2 -> Strawberry | V10: IV | W10: BN
A11: =IF(COUNTIF($V$3:$Y$99, $B11)<>0, ROW($B11), 0) -> 0 | B11: Thistly Cross Selection Box Gift Box | C11: 140 | D11: 4 | F11: {=INDEX(OFFSET(INDIRECT("A"&F10), 1, 0):OFFSET(OFFSET(INDIRECT("A"&F10), 1, 0), 100, 0),MATCH(TRUE,INDEX(OFFSET(INDIRECT("A"&F10), 1, 0):OFFSET(OFFSET(INDIRECT("A"&F10), 1, 0), 100, 0)<>0,),0))} -> 235 | G11: {=INDIRECT("B"&$F11)} -> G | H11: {=_xlfn.IFS(COUNTIF($V$3:$V$18, G11)<>0, "S", COUNTIF($W$3:$W$99, G11)<>0, "E", COUNTIF($X$3, G11)<>0, "I", COUNTIF($Y$3:$Y$8, G11)<>0, "W")} -> S | I11: =SUMIF(OFFSET(INDIRECT("B"&$F11), 4, 0):INDIRECT("B"&$F12), "*"&$I$2&"*", OFFSET(INDIRECT("C"&$F11), 4, 0):OFFSET(INDIRECT("C"&$F12), -1, 0)) -> 2356.75 | J11: =SUMIF(OFFSET(INDIRECT("B"&$F11), 4, 0):INDIRECT("B"&$F12), "*"&$J$2&"*", OFFSET(INDIRECT("C"&$F11), 4, 0):OFFSET(INDIRECT("C"&$F12), -1, 0)) -> 407.36 | K11: =SUMIF(OFFSET(INDIRECT("B"&$F11), 4, 0):INDIRECT("B"&$F12), "*"&$K$2&"*", OFFSET(INDIRECT("C"&$F11), 4, 0):OFFSET(INDIRECT("C"&$F12), -1, 0)) -> 469.15 | L11: =SUMIF(OFFSET(INDIRECT("B"&$F11), 4, 0):INDIRECT("B"&$F12), "*"&$L$2&"*", OFFSET(INDIRECT("C"&$F11), 4, 0):OFFSET(INDIRECT("C"&$F12), -1, 0)) -> 817.51 | M11: =SUMIF(OFFSET(INDIRECT("B"&$F11), 4, 0):INDIRECT("B"&$F12), "*"&$M$2&"*", OFFSET(INDIRECT("C"&$F11), 4, 0):OFFSET(INDIRECT("C"&$F12), -1, 0)) -> 802.4 | N11: =SUMIF(OFFSET(INDIRECT("B"&$F11), 4, 0):INDIRECT("B"&$F12), "*"&$N$2&"*", OFFSET(INDIRECT("C"&$F11), 4, 0):OFFSET(INDIRECT("C"&$F12), -1, 0)) -> 322.26 | O11: =SUMIF(OFFSET(INDIRECT("B"&$F11), 4, 0):INDIRECT("B"&$F12), "*"&$O$2&"*", OFFSET(INDIRECT("C"&$F11), 4, 0):OFFSET(INDIRECT("C"&$F12), -1, 0)) -> 230.4 | P11: =SUMIF(OFFSET(INDIRECT("B"&$F11), 4, 0):INDIRECT("B"&$F12), "*"&$P$2&"*", OFFSET(INDIRECT("C"&$F11), 4, 0):OFFSET(INDIRECT("C"&$F12), -1, 0)) -> 2691.6 | Q11: =SUM($I11:$P11) -> 8097.43 | S11: Region | T11: Sales | V11: KA | W11: BR
A12: =IF(COUNTIF($V$3:$Y$99, $B12)<>0, ROW($B12), 0) -> 0 | B12: Original - Bottle 24 x 330ml | C12: 153.6 | D12: 4 | F12: {=INDEX(OFFSET(INDIRECT("A"&F11), 1, 0):OFFSET(OFFSET(INDIRECT("A"&F11), 1, 0), 100, 0),MATCH(TRUE,INDEX(OFFSET(INDIRECT("A"&F11), 1, 0):OFFSET(OFFSET(INDIRECT("A"&F11), 1, 0), 100, 0)<>0,),0))} -> 284 | G12: {=INDIRECT("B"&$F12)} -> CB | H12: {=_xlfn.IFS(COUNTIF($V$3:$V$18, G12)<>0, "S", COUNTIF($W$3:$W$99, G12)<>0, "E", COUNTIF($X$3, G12)<>0, "I", COUNTIF($Y$3:$Y$8, G12)<>0, "W")} -> E | I12: =SUMIF(OFFSET(INDIRECT("B"&$F12), 4, 0):INDIRECT("B"&$F13), "*"&$I$2&"*", OFFSET(INDIRECT("C"&$F12), 4, 0):OFFSET(INDIRECT("C"&$F13), -1, 0)) -> 506.8 | J12: =SUMIF(OFFSET(INDIRECT("B"&$F12), 4, 0):INDIRECT("B"&$F13), "*"&$J$2&"*", OFFSET(INDIRECT("C"&$F12), 4, 0):OFFSET(INDIRECT("C"&$F13), -1, 0)) -> 38.4 | K12: =SUMIF(OFFSET(INDIRECT("B"&$F12), 4, 0):INDIRECT("B"&$F13), "*"&$K$2&"*", OFFSET(INDIRECT("C"&$F12), 4, 0):OFFSET(INDIRECT("C"&$F13), -1, 0)) -> 0 | L12: =SUMIF(OFFSET(INDIRECT("B"&$F12), 4, 0):INDIRECT("B"&$F13), "*"&$L$2&"*", OFFSET(INDIRECT("C"&$F12), 4, 0):OFFSET(INDIRECT("C"&$F13), -1, 0)) -> 78.4 | M12: =SUMIF(OFFSET(INDIRECT("B"&$F12), 4, 0):INDIRECT("B"&$F13), "*"&$M$2&"*", OFFSET(INDIRECT("C"&$F12), 4, 0):OFFSET(INDIRECT("C"&$F13), -1, 0)) -> 299.6 | N12: =SUMIF(OFFSET(INDIRECT("B"&$F12), 4, 0):INDIRECT("B"&$F13), "*"&$N$2&"*", OFFSET(INDIRECT("C"&$F12), 4, 0):OFFSET(INDIRECT("C"&$F13), -1, 0)) -> 67.15 | O12: =SUMIF(OFFSET(INDIRECT("B"&$F12), 4, 0):INDIRECT("B"&$F13), "*"&$O$2&"*", OFFSET(INDIRECT("C"&$F12), 4, 0):OFFSET(INDIRECT("C"&$F13), -1, 0)) -> 115.2 | P12: =SUMIF(OFFSET(INDIRECT("B"&$F12), 4, 0):INDIRECT("B"&$F13), "*"&$P$2&"*", OFFSET(INDIRECT("C"&$F12), 4, 0):OFFSET(INDIRECT("C"&$F13), -1, 0)) -> 313.95 | Q12: =SUM($I12:$P12) -> 1419.5 | S12: England | T12: =SUMIF($H$3:$H$120, "E", $J$3:$J$120) -> 4733.07 | V12: KW | W12: BS
A13: =IF(COUNTIF($V$3:$Y$99, $B13)<>0, ROW($B13), 0) -> 0 | B13: Traditional Cider Liqueur 50cl | C13: 28.75 | D13: 1 | F13: {=INDEX(OFFSET(INDIRECT("A"&F12), 1, 0):OFFSET(OFFSET(INDIRECT("A"&F12), 1, 0), 100, 0),MATCH(TRUE,INDEX(OFFSET(INDIRECT("A"&F12), 1, 0):OFFSET(OFFSET(INDIRECT("A"&F12), 1, 0), 100, 0)<>0,),0))} -> 309 | G13: {=INDIRECT("B"&$F13)} -> CF | H13: {=_xlfn.IFS(COUNTIF($V$3:$V$18, G13)<>0, "S", COUNTIF($W$3:$W$99, G13)<>0, "E", COUNTIF($X$3, G13)<>0, "I", COUNTIF($Y$3:$Y$8, G13)<>0, "W")} -> W | I13: =SUMIF(OFFSET(INDIRECT("B"&$F13), 4, 0):INDIRECT("B"&$F14), "*"&$I$2&"*", OFFSET(INDIRECT("C"&$F13), 4, 0):OFFSET(INDIRECT("C"&$F14), -1, 0)) -> 1493.85 | J13: =SUMIF(OFFSET(INDIRECT("B"&$F13), 4, 0):INDIRECT("B"&$F14), "*"&$J$2&"*", OFFSET(INDIRECT("C"&$F13), 4, 0):OFFSET(INDIRECT("C"&$F14), -1, 0)) -> 166.75 | K13: =SUMIF(OFFSET(INDIRECT("B"&$F13), 4, 0):INDIRECT("B"&$F14), "*"&$K$2&"*", OFFSET(INDIRECT("C"&$F13), 4, 0):OFFSET(INDIRECT("C"&$F14), -1, 0)) -> 54.8 | L13: =SUMIF(OFFSET(INDIRECT("B"&$F13), 4, 0):INDIRECT("B"&$F14), "*"&$L$2&"*", OFFSET(INDIRECT("C"&$F13), 4, 0):OFFSET(INDIRECT("C"&$F14), -1, 0)) -> 430.64 | M13: =SUMIF(OFFSET(INDIRECT("B"&$F13), 4, 0):INDIRECT("B"&$F14), "*"&$M$2&"*", OFFSET(INDIRECT("C"&$F13), 4, 0):OFFSET(INDIRECT("C"&$F14), -1, 0)) -> 38.4 | N13: =SUMIF(OFFSET(INDIRECT("B"&$F13), 4, 0):INDIRECT("B"&$F14), "*"&$N$2&"*", OFFSET(INDIRECT("C"&$F13), 4, 0):OFFSET(INDIRECT("C"&$F14), -1, 0)) -> 28.75 | O13: =SUMIF(OFFSET(INDIRECT("B"&$F13), 4, 0):INDIRECT("B"&$F14), "*"&$O$2&"*", OFFSET(INDIRECT("C"&$F13), 4, 0):OFFSET(INDIRECT("C"&$F14), -1, 0)) -> 38.4 | P13: =SUMIF(OFFSET(INDIRECT("B"&$F13), 4, 0):INDIRECT("B"&$F14), "*"&$P$2&"*", OFFSET(INDIRECT("C"&$F13), 4, 0):OFFSET(INDIRECT("C"&$F14), -1, 0)) -> 805 | Q13: =SUM($I13:$P13) -> 3056.59 | S13: Scotland | T13: =SUMIF($H$3:$H$120, "S", $J$3:$J$120) -> 5786.31 | V13: KY | W13: CA
A14: =IF(COUNTIF($V$3:$Y$99, $B14)<>0, ROW($B14), 0) -> 0 | B14: Whisky Cask - 20L Ciderbox 20L Ciderbox | C14: 408 | D14: 6 | F14: {=INDEX(OFFSET(INDIRECT("A"&F13), 1, 0):OFFSET(OFFSET(INDIRECT("A"&F13), 1, 0), 100, 0),MATCH(TRUE,INDEX(OFFSET(INDIRECT("A"&F13), 1, 0):OFFSET(OFFSET(INDIRECT("A"&F13), 1, 0), 100, 0)<>0,),0))} -> 339 | G14: {=INDIRECT("B"&$F14)} -> EH | H14: {=_xlfn.IFS(COUNTIF($V$3:$V$18, G14)<>0, "S", COUNTIF($W$3:$W$99, G14)<>0, "E", COUNTIF($X$3, G14)<>0, "I", COUNTIF($Y$3:$Y$8, G14)<>0, "W")} -> S | I14: =SUMIF(OFFSET(INDIRECT("B"&$F14), 4, 0):INDIRECT("B"&$F15), "*"&$I$2&"*", OFFSET(INDIRECT("C"&$F14), 4, 0):OFFSET(INDIRECT("C"&$F15), -1, 0)) -> 5327.2 | J14: =SUMIF(OFFSET(INDIRECT("B"&$F14), 4, 0):INDIRECT("B"&$F15), "*"&$J$2&"*", OFFSET(INDIRECT("C"&$F14), 4, 0):OFFSET(INDIRECT("C"&$F15), -1, 0)) -> 1291.68 | K14: =SUMIF(OFFSET(INDIRECT("B"&$F14), 4, 0):INDIRECT("B"&$F15), "*"&$K$2&"*", OFFSET(INDIRECT("C"&$F14), 4, 0):OFFSET(INDIRECT("C"&$F15), -1, 0)) -> 1570.17 | L14: =SUMIF(OFFSET(INDIRECT("B"&$F14), 4, 0):INDIRECT("B"&$F15), "*"&$L$2&"*", OFFSET(INDIRECT("C"&$F14), 4, 0):OFFSET(INDIRECT("C"&$F15), -1, 0)) -> 2952.98 | M14: =SUMIF(OFFSET(INDIRECT("B"&$F14), 4, 0):INDIRECT("B"&$F15), "*"&$M$2&"*", OFFSET(INDIRECT("C"&$F14), 4, 0):OFFSET(INDIRECT("C"&$F15), -1, 0)) -> 3640.8 | N14: =SUMIF(OFFSET(INDIRECT("B"&$F14), 4, 0):INDIRECT("B"&$F15), "*"&$N$2&"*", OFFSET(INDIRECT("C"&$F14), 4, 0):OFFSET(INDIRECT("C"&$F15), -1, 0)) -> 1300.76 | O14: =SUMIF(OFFSET(INDIRECT("B"&$F14), 4, 0):INDIRECT("B"&$F15), "*"&$O$2&"*", OFFSET(INDIRECT("C"&$F14), 4, 0):OFFSET(INDIRECT("C"&$F15), -1, 0)) -> 617.6 | P14: =SUMIF(OFFSET(INDIRECT("B"&$F14), 4, 0):INDIRECT("B"&$F15), "*"&$P$2&"*", OFFSET(INDIRECT("C"&$F14), 4, 0):OFFSET(INDIRECT("C"&$F15), -1, 0)) -> 8093.19 | Q14: =SUM($I14:$P14) -> 24794.38 | S14: N.Ireland | T14: =SUMIF($H$3:$H$120, "I", $J$3:$J$120) -> 0 | V14: ML | W14: CB
A15: =IF(COUNTIF($V$3:$Y$99, $B15)<>0, ROW($B15), 0) -> 0 | B15: Whisky Cask - 10L Ciderbox 10L | C15: 35.2 | D15: 1 | F15: {=INDEX(OFFSET(INDIRECT("A"&F14), 1, 0):OFFSET(OFFSET(INDIRECT("A"&F14), 1, 0), 100, 0),MATCH(TRUE,INDEX(OFFSET(INDIRECT("A"&F14), 1, 0):OFFSET(OFFSET(INDIRECT("A"&F14), 1, 0), 100, 0)<>0,),0))} -> 399 | G15: {=INDIRECT("B"&$F15)} -> IP | H15: {=_xlfn.IFS(COUNTIF($V$3:$V$18, G15)<>0, "S", COUNTIF($W$3:$W$99, G15)<>0, "E", COUNTIF($X$3, G15)<>0, "I", COUNTIF($Y$3:$Y$8, G15)<>0, "W")} -> E | I15: =SUMIF(OFFSET(INDIRECT("B"&$F15), 4, 0):INDIRECT("B"&$F16), "*"&$I$2&"*", OFFSET(INDIRECT("C"&$F15), 4, 0):OFFSET(INDIRECT("C"&$F16), -1, 0)) -> 402 | J15: =SUMIF(OFFSET(INDIRECT("B"&$F15), 4, 0):INDIRECT("B"&$F16), "*"&$J$2&"*", OFFSET(INDIRECT("C"&$F15), 4, 0):OFFSET(INDIRECT("C"&$F16), -1, 0)) -> 198.96 | K15: =SUMIF(OFFSET(INDIRECT("B"&$F15), 4, 0):INDIRECT("B"&$F16), "*"&$K$2&"*", OFFSET(INDIRECT("C"&$F15), 4, 0):OFFSET(INDIRECT("C"&$F16), -1, 0)) -> 76.8 | L15: =SUMIF(OFFSET(INDIRECT("B"&$F15), 4, 0):INDIRECT("B"&$F16), "*"&$L$2&"*", OFFSET(INDIRECT("C"&$F15), 4, 0):OFFSET(INDIRECT("C"&$F16), -1, 0)) -> 54.8 | M15: =SUMIF(OFFSET(INDIRECT("B"&$F15), 4, 0):INDIRECT("B"&$F16), "*"&$M$2&"*", OFFSET(INDIRECT("C"&$F15), 4, 0):OFFSET(INDIRECT("C"&$F16), -1, 0)) -> 0 | N15: =SUMIF(OFFSET(INDIRECT("B"&$F15), 4, 0):INDIRECT("B"&$F16), "*"&$N$2&"*", OFFSET(INDIRECT("C"&$F15), 4, 0):OFFSET(INDIRECT("C"&$F16), -1, 0)) -> 63.31 | O15: =SUMIF(OFFSET(INDIRECT("B"&$F15), 4, 0):INDIRECT("B"&$F16), "*"&$O$2&"*", OFFSET(INDIRECT("C"&$F15), 4, 0):OFFSET(INDIRECT("C"&$F16), -1, 0)) -> 0 | P15: =SUMIF(OFFSET(INDIRECT("B"&$F15), 4, 0):INDIRECT("B"&$F16), "*"&$P$2&"*", OFFSET(INDIRECT("C"&$F15), 4, 0):OFFSET(INDIRECT("C"&$F16), -1, 0)) -> 192 | Q15: =SUM($I15:$P15) -> 987.87 | S15: Wales | T15: =SUMIF($H$3:$H$120, "W", $J$3:$J$120) -> 221.55 | V15: PA | W15: CH
A16: =IF(COUNTIF($V$3:$Y$99, $B16)<>0, ROW($B16), 0) -> 0 | B16: Traditional - Bottle 24 x 330ml | C16: 153.6 | D16: 4 | F16: {=INDEX(OFFSET(INDIRECT("A"&F15), 1, 0):OFFSET(OFFSET(INDIRECT("A"&F15), 1, 0), 100, 0),MATCH(TRUE,INDEX(OFFSET(INDIRECT("A"&F15), 1, 0):OFFSET(OFFSET(INDIRECT("A"&F15), 1, 0), 100, 0)<>0,),0))} -> 419 | G16: {=INDIRECT("B"&$F16)} -> BT | H16: {=_xlfn.IFS(COUNTIF($V$3:$V$18, G16)<>0, "S", COUNTIF($W$3:$W$99, G16)<>0, "E", COUNTIF($X$3, G16)<>0, "I", COUNTIF($Y$3:$Y$8, G16)<>0, "W")} -> I | I16: =SUMIF(OFFSET(INDIRECT("B"&$F16), 4, 0):INDIRECT("B"&$F17), "*"&$I$2&"*", OFFSET(INDIRECT("C"&$F16), 4, 0):OFFSET(INDIRECT("C"&$F17), -1, 0)) -> 694 | J16: =SUMIF(OFFSET(INDIRECT("B"&$F16), 4, 0):INDIRECT("B"&$F17), "*"&$J$2&"*", OFFSET(INDIRECT("C"&$F16), 4, 0):OFFSET(INDIRECT("C"&$F17), -1, 0)) -> 0 | K16: =SUMIF(OFFSET(INDIRECT("B"&$F16), 4, 0):INDIRECT("B"&$F17), "*"&$K$2&"*", OFFSET(INDIRECT("C"&$F16), 4, 0):OFFSET(INDIRECT("C"&$F17), -1, 0)) -> 0 | L16: =SUMIF(OFFSET(INDIRECT("B"&$F16), 4, 0):INDIRECT("B"&$F17), "*"&$L$2&"*", OFFSET(INDIRECT("C"&$F16), 4, 0):OFFSET(INDIRECT("C"&$F17), -1, 0)) -> 109.19 | M16: =SUMIF(OFFSET(INDIRECT("B"&$F16), 4, 0):INDIRECT("B"&$F17), "*"&$M$2&"*", OFFSET(INDIRECT("C"&$F16), 4, 0):OFFSET(INDIRECT("C"&$F17), -1, 0)) -> 94.8 | N16: =SUMIF(OFFSET(INDIRECT("B"&$F16), 4, 0):INDIRECT("B"&$F17), "*"&$N$2&"*", OFFSET(INDIRECT("C"&$F16), 4, 0):OFFSET(INDIRECT("C"&$F17), -1, 0)) -> 28.75 | O16: =SUMIF(OFFSET(INDIRECT("B"&$F16), 4, 0):INDIRECT("B"&$F17), "*"&$O$2&"*", OFFSET(INDIRECT("C"&$F16), 4, 0):OFFSET(INDIRECT("C"&$F17), -1, 0)) -> 0 | P16: =SUMIF(OFFSET(INDIRECT("B"&$F16), 4, 0):INDIRECT("B"&$F17), "*"&$P$2&"*", OFFSET(INDIRECT("C"&$F16), 4, 0):OFFSET(INDIRECT("C"&$F17), -1, 0)) -> 421.1 | Q16: =SUM($I16:$P16) -> 1347.84 | S16: Total | T16: =SUM(T12:T15) -> 10740.93 | V16: PH | W16: CM
A17: =IF(COUNTIF($V$3:$Y$99, $B17)<>0, ROW($B17), 0) -> 0 | B17: Mix & Match 330ml Bottle Case (24 Bottles) | C17: 76.8 | D17: 2 | F17: {=INDEX(OFFSET(INDIRECT("A"&F16), 1, 0):OFFSET(OFFSET(INDIRECT("A"&F16), 1, 0), 100, 0),MATCH(TRUE,INDEX(OFFSET(INDIRECT("A"&F16), 1, 0):OFFSET(OFFSET(INDIRECT("A"&F16), 1, 0), 100, 0)<>0,),0))} -> 446 | G17: {=INDIRECT("B"&$F17)} -> B | H17: {=_xlfn.IFS(COUNTIF($V$3:$V$18, G17)<>0, "S", COUNTIF($W$3:$W$99, G17)<>0, "E", COUNTIF($X$3, G17)<>0, "I", COUNTIF($Y$3:$Y$8, G17)<>0, "W")} -> E | I17: =SUMIF(OFFSET(INDIRECT("B"&$F17), 4, 0):INDIRECT("B"&$F18), "*"&$I$2&"*", OFFSET(INDIRECT("C"&$F17), 4, 0):OFFSET(INDIRECT("C"&$F18), -1, 0)) -> 1544.35 | J17: =SUMIF(OFFSET(INDIRECT("B"&$F17), 4, 0):INDIRECT("B"&$F18), "*"&$J$2&"*", OFFSET(INDIRECT("C"&$F17), 4, 0):OFFSET(INDIRECT("C"&$F18), -1, 0)) -> 40 | K17: =SUMIF(OFFSET(INDIRECT("B"&$F17), 4, 0):INDIRECT("B"&$F18), "*"&$K$2&"*", OFFSET(INDIRECT("C"&$F17), 4, 0):OFFSET(INDIRECT("C"&$F18), -1, 0)) -> 0 | L17: =SUMIF(OFFSET(INDIRECT("B"&$F17), 4, 0):INDIRECT("B"&$F18), "*"&$L$2&"*", OFFSET(INDIRECT("C"&$F17), 4, 0):OFFSET(INDIRECT("C"&$F18), -1, 0)) -> 570.34 | M17: =SUMIF(OFFSET(INDIRECT("B"&$F17), 4, 0):INDIRECT("B"&$F18), "*"&$M$2&"*", OFFSET(INDIRECT("C"&$F17), 4, 0):OFFSET(INDIRECT("C"&$F18), -1, 0)) -> 262.8 | N17: =SUMIF(OFFSET(INDIRECT("B"&$F17), 4, 0):INDIRECT("B"&$F18), "*"&$N$2&"*", OFFSET(INDIRECT("C"&$F17), 4, 0):OFFSET(INDIRECT("C"&$F18), -1, 0)) -> 28.75 | O17: =SUMIF(OFFSET(INDIRECT("B"&$F17), 4, 0):INDIRECT("B"&$F18), "*"&$O$2&"*", OFFSET(INDIRECT("C"&$F17), 4, 0):OFFSET(INDIRECT("C"&$F18), -1, 0)) -> 64 | P17: =SUMIF(OFFSET(INDIRECT("B"&$F17), 4, 0):INDIRECT("B"&$F18), "*"&$P$2&"*", OFFSET(INDIRECT("C"&$F17), 4, 0):OFFSET(INDIRECT("C"&$F18), -1, 0)) -> 347.2 | Q17: =SUM($I17:$P17) -> 2857.44 | V17: TD | W17: CO
A18: =IF(COUNTIF($V$3:$Y$99, $B18)<>0, ROW($B18), 0) -> 0 | B18: Scottish Fruits Cider Liqueur 50cl | C18: 28.75 | D18: 3 | F18: {=INDEX(OFFSET(INDIRECT("A"&F17), 1, 0):OFFSET(OFFSET(INDIRECT("A"&F17), 1, 0), 100, 0),MATCH(TRUE,INDEX(OFFSET(INDIRECT("A"&F17), 1, 0):OFFSET(OFFSET(INDIRECT("A"&F17), 1, 0), 100, 0)<>0,),0))} -> 474 | G18: {=INDIRECT("B"&$F18)} -> NG | H18: {=_xlfn.IFS(COUNTIF($V$3:$V$18, G18)<>0, "S", COUNTIF($W$3:$W$99, G18)<>0, "E", COUNTIF($X$3, G18)<>0, "I", COUNTIF($Y$3:$Y$8, G18)<>0, "W")} -> E | I18: =SUMIF(OFFSET(INDIRECT("B"&$F18), 4, 0):INDIRECT("B"&$F19), "*"&$I$2&"*", OFFSET(INDIRECT("C"&$F18), 4, 0):OFFSET(INDIRECT("C"&$F19), -1, 0)) -> 1998.8 | J18: =SUMIF(OFFSET(INDIRECT("B"&$F18), 4, 0):INDIRECT("B"&$F19), "*"&$J$2&"*", OFFSET(INDIRECT("C"&$F18), 4, 0):OFFSET(INDIRECT("C"&$F19), -1, 0)) -> 111.36 | K18: =SUMIF(OFFSET(INDIRECT("B"&$F18), 4, 0):INDIRECT("B"&$F19), "*"&$K$2&"*", OFFSET(INDIRECT("C"&$F18), 4, 0):OFFSET(INDIRECT("C"&$F19), -1, 0)) -> 0 | L18: =SUMIF(OFFSET(INDIRECT("B"&$F18), 4, 0):INDIRECT("B"&$F19), "*"&$L$2&"*", OFFSET(INDIRECT("C"&$F18), 4, 0):OFFSET(INDIRECT("C"&$F19), -1, 0)) -> 174.1 | M18: =SUMIF(OFFSET(INDIRECT("B"&$F18), 4, 0):INDIRECT("B"&$F19), "*"&$M$2&"*", OFFSET(INDIRECT("C"&$F18), 4, 0):OFFSET(INDIRECT("C"&$F19), -1, 0)) -> 195.6 | N18: =SUMIF(OFFSET(INDIRECT("B"&$F18), 4, 0):INDIRECT("B"&$F19), "*"&$N$2&"*", OFFSET(INDIRECT("C"&$F18), 4, 0):OFFSET(INDIRECT("C"&$F19), -1, 0)) -> 140.11 | O18: =SUMIF(OFFSET(INDIRECT("B"&$F18), 4, 0):INDIRECT("B"&$F19), "*"&$O$2&"*", OFFSET(INDIRECT("C"&$F18), 4, 0):OFFSET(INDIRECT("C"&$F19), -1, 0)) -> 76.8 | P18: =SUMIF(OFFSET(INDIRECT("B"&$F18), 4, 0):INDIRECT("B"&$F19), "*"&$P$2&"*", OFFSET(INDIRECT("C"&$F18), 4, 0):OFFSET(INDIRECT("C"&$F19), -1, 0)) -> 532 | Q18: =SUM($I18:$P18) -> 3228.77 | S18: =K2 -> Ginger | V18: ZE | W18: CR
A19: =IF(COUNTIF($V$3:$Y$99, $B19)<>0, ROW($B19), 0) -> 0 | B19: Whisky Cask - Bottle 24 x 330ml | C19: 307.2 | D19: 8 | F19: {=INDEX(OFFSET(INDIRECT("A"&F18), 1, 0):OFFSET(OFFSET(INDIRECT("A"&F18), 1, 0), 100, 0),MATCH(TRUE,INDEX(OFFSET(INDIRECT("A"&F18), 1, 0):OFFSET(OFFSET(INDIRECT("A"&F18), 1, 0), 100, 0)<>0,),0))} -> 506 | G19: {=INDIRECT("B"&$F19)} -> IV | H19: {=_xlfn.IFS(COUNTIF($V$3:$V$18, G19)<>0, "S", COUNTIF($W$3:$W$99, G19)<>0, "E", COUNTIF($X$3, G19)<>0, "I", COUNTIF($Y$3:$Y$8, G19)<>0, "W")} -> S | I19: =SUMIF(OFFSET(INDIRECT("B"&$F19), 4, 0):INDIRECT("B"&$F20), "*"&$I$2&"*", OFFSET(INDIRECT("C"&$F19), 4, 0):OFFSET(INDIRECT("C"&$F20), -1, 0)) -> 2051.15 | J19: =SUMIF(OFFSET(INDIRECT("B"&$F19), 4, 0):INDIRECT("B"&$F20), "*"&$J$2&"*", OFFSET(INDIRECT("C"&$F19), 4, 0):OFFSET(INDIRECT("C"&$F20), -1, 0)) -> 305.47 | K19: =SUMIF(OFFSET(INDIRECT("B"&$F19), 4, 0):INDIRECT("B"&$F20), "*"&$K$2&"*", OFFSET(INDIRECT("C"&$F19), 4, 0):OFFSET(INDIRECT("C"&$F20), -1, 0)) -> 227.5 | L19: =SUMIF(OFFSET(INDIRECT("B"&$F19), 4, 0):INDIRECT("B"&$F20), "*"&$L$2&"*", OFFSET(INDIRECT("C"&$F19), 4, 0):OFFSET(INDIRECT("C"&$F20), -1, 0)) -> 517.55 | M19: =SUMIF(OFFSET(INDIRECT("B"&$F19), 4, 0):INDIRECT("B"&$F20), "*"&$M$2&"*", OFFSET(INDIRECT("C"&$F19), 4, 0):OFFSET(INDIRECT("C"&$F20), -1, 0)) -> 577.2 | N19: =SUMIF(OFFSET(INDIRECT("B"&$F19), 4, 0):INDIRECT("B"&$F20), "*"&$N$2&"*", OFFSET(INDIRECT("C"&$F19), 4, 0):OFFSET(INDIRECT("C"&$F20), -1, 0)) -> 272.54 | O19: =SUMIF(OFFSET(INDIRECT("B"&$F19), 4, 0):INDIRECT("B"&$F20), "*"&$O$2&"*", OFFSET(INDIRECT("C"&$F19), 4, 0):OFFSET(INDIRECT("C"&$F20), -1, 0)) -> 217.6 | P19: =SUMIF(OFFSET(INDIRECT("B"&$F19), 4, 0):INDIRECT("B"&$F20), "*"&$P$2&"*", OFFSET(INDIRECT("C"&$F19), 4, 0):OFFSET(INDIRECT("C"&$F20), -1, 0)) -> 2392.5 | Q19: =SUM($I19:$P19) -> 6561.51 | S19: Region | T19: Sales | W19: CT
A20: =IF(COUNTIF($V$3:$Y$99, $B20)<>0, ROW($B20), 0) -> 0 | B20: Mix & Match 500ml Bottle Case (24 bottles) | C20: 328.8 | D20: 6 | F20: {=INDEX(OFFSET(INDIRECT("A"&F19), 1, 0):OFFSET(OFFSET(INDIRECT("A"&F19), 1, 0), 100, 0),MATCH(TRUE,INDEX(OFFSET(INDIRECT("A"&F19), 1, 0):OFFSET(OFFSET(INDIRECT("A"&F19), 1, 0), 100, 0)<>0,),0))} -> 551 | G20: {=INDIRECT("B"&$F20)} -> HA | H20: {=_xlfn.IFS(COUNTIF($V$3:$V$18, G20)<>0, "S", COUNTIF($W$3:$W$99, G20)<>0, "E", COUNTIF($X$3, G20)<>0, "I", COUNTIF($Y$3:$Y$8, G20)<>0, "W")} -> E | I20: =SUMIF(OFFSET(INDIRECT("B"&$F20), 4, 0):INDIRECT("B"&$F21), "*"&$I$2&"*", OFFSET(INDIRECT("C"&$F20), 4, 0):OFFSET(INDIRECT("C"&$F21), -1, 0)) -> 224.8 | J20: =SUMIF(OFFSET(INDIRECT("B"&$F20), 4, 0):INDIRECT("B"&$F21), "*"&$J$2&"*", OFFSET(INDIRECT("C"&$F20), 4, 0):OFFSET(INDIRECT("C"&$F21), -1, 0)) -> 0 | K20: =SUMIF(OFFSET(INDIRECT("B"&$F20), 4, 0):INDIRECT("B"&$F21), "*"&$K$2&"*", OFFSET(INDIRECT("C"&$F20), 4, 0):OFFSET(INDIRECT("C"&$F21), -1, 0)) -> 38.4 | L20: =SUMIF(OFFSET(INDIRECT("B"&$F20), 4, 0):INDIRECT("B"&$F21), "*"&$L$2&"*", OFFSET(INDIRECT("C"&$F20), 4, 0):OFFSET(INDIRECT("C"&$F21), -1, 0)) -> 76.8 | M20: =SUMIF(OFFSET(INDIRECT("B"&$F20), 4, 0):INDIRECT("B"&$F21), "*"&$M$2&"*", OFFSET(INDIRECT("C"&$F20), 4, 0):OFFSET(INDIRECT("C"&$F21), -1, 0)) -> 38.4 | N20: =SUMIF(OFFSET(INDIRECT("B"&$F20), 4, 0):INDIRECT("B"&$F21), "*"&$N$2&"*", OFFSET(INDIRECT("C"&$F20), 4, 0):OFFSET(INDIRECT("C"&$F21), -1, 0)) -> 0 | O20: =SUMIF(OFFSET(INDIRECT("B"&$F20), 4, 0):INDIRECT("B"&$F21), "*"&$O$2&"*", OFFSET(INDIRECT("C"&$F20), 4, 0):OFFSET(INDIRECT("C"&$F21), -1, 0)) -> 0 | P20: =SUMIF(OFFSET(INDIRECT("B"&$F20), 4, 0):INDIRECT("B"&$F21), "*"&$P$2&"*", OFFSET(INDIRECT("C"&$F20), 4, 0):OFFSET(INDIRECT("C"&$F21), -1, 0)) -> 238.75 | Q20: =SUM($I20:$P20) -> 617.15 | S20: England | T20: =SUMIF($H$3:$H$120, "E", $K$3:$K$120) -> 3128.3 | W20: CV
A21: =IF(COUNTIF($V$3:$Y$99, $B21)<>0, ROW($B21), 0) -> 0 | B21: Elderflower - Bottle 24 x 500ml | C21: 54.8 | D21: 1 | F21: {=INDEX(OFFSET(INDIRECT("A"&F20), 1, 0):OFFSET(OFFSET(INDIRECT("A"&F20), 1, 0), 100, 0),MATCH(TRUE,INDEX(OFFSET(INDIRECT("A"&F20), 1, 0):OFFSET(OFFSET(INDIRECT("A"&F20), 1, 0), 100, 0)<>0,),0))} -> 567 | G21: {=INDIRECT("B"&$F21)} -> S | H21: {=_xlfn.IFS(COUNTIF($V$3:$V$18, G21)<>0, "S", COUNTIF($W$3:$W$99, G21)<>0, "E", COUNTIF($X$3, G21)<>0, "I", COUNTIF($Y$3:$Y$8, G21)<>0, "W")} -> E | I21: =SUMIF(OFFSET(INDIRECT("B"&$F21), 4, 0):INDIRECT("B"&$F22), "*"&$I$2&"*", OFFSET(INDIRECT("C"&$F21), 4, 0):OFFSET(INDIRECT("C"&$F22), -1, 0)) -> 1793.15 | J21: =SUMIF(OFFSET(INDIRECT("B"&$F21), 4, 0):INDIRECT("B"&$F22), "*"&$J$2&"*", OFFSET(INDIRECT("C"&$F21), 4, 0):OFFSET(INDIRECT("C"&$F22), -1, 0)) -> 76.8 | K21: =SUMIF(OFFSET(INDIRECT("B"&$F21), 4, 0):INDIRECT("B"&$F22), "*"&$K$2&"*", OFFSET(INDIRECT("C"&$F21), 4, 0):OFFSET(INDIRECT("C"&$F22), -1, 0)) -> 116.8 | L21: =SUMIF(OFFSET(INDIRECT("B"&$F21), 4, 0):INDIRECT("B"&$F22), "*"&$L$2&"*", OFFSET(INDIRECT("C"&$F21), 4, 0):OFFSET(INDIRECT("C"&$F22), -1, 0)) -> 181.55 | M21: =SUMIF(OFFSET(INDIRECT("B"&$F21), 4, 0):INDIRECT("B"&$F22), "*"&$M$2&"*", OFFSET(INDIRECT("C"&$F21), 4, 0):OFFSET(INDIRECT("C"&$F22), -1, 0)) -> 238.8 | N21: =SUMIF(OFFSET(INDIRECT("B"&$F21), 4, 0):INDIRECT("B"&$F22), "*"&$N$2&"*", OFFSET(INDIRECT("C"&$F21), 4, 0):OFFSET(INDIRECT("C"&$F22), -1, 0)) -> 120.81 | O21: =SUMIF(OFFSET(INDIRECT("B"&$F21), 4, 0):INDIRECT("B"&$F22), "*"&$O$2&"*", OFFSET(INDIRECT("C"&$F21), 4, 0):OFFSET(INDIRECT("C"&$F22), -1, 0)) -> 64 | P21: =SUMIF(OFFSET(INDIRECT("B"&$F21), 4, 0):INDIRECT("B"&$F22), "*"&$P$2&"*", OFFSET(INDIRECT("C"&$F21), 4, 0):OFFSET(INDIRECT("C"&$F22), -1, 0)) -> 423.55 | Q21: =SUM($I21:$P21) -> 3015.46 | S21: Scotland | T21: =SUMIF($H$3:$H$120, "S", $K$3:$K$120) -> 3858.17 | W21: CW
A22: =IF(COUNTIF($V$3:$Y$99, $B22)<>0, ROW($B22), 0) -> 0 | B22: MIx + Match 500ml - March Offer | C22: 49.95 | D22: 1 | F22: {=INDEX(OFFSET(INDIRECT("A"&F21), 1, 0):OFFSET(OFFSET(INDIRECT("A"&F21), 1, 0), 100, 0),MATCH(TRUE,INDEX(OFFSET(INDIRECT("A"&F21), 1, 0):OFFSET(OFFSET(INDIRECT("A"&F21), 1, 0), 100, 0)<>0,),0))} -> 599 | G22: {=INDIRECT("B"&$F22)} -> SY | H22: {=_xlfn.IFS(COUNTIF($V$3:$V$18, G22)<>0, "S", COUNTIF($W$3:$W$99, G22)<>0, "E", COUNTIF($X$3, G22)<>0, "I", COUNTIF($Y$3:$Y$8, G22)<>0, "W")} -> W | I22: =SUMIF(OFFSET(INDIRECT("B"&$F22), 4, 0):INDIRECT("B"&$F23), "*"&$I$2&"*", OFFSET(INDIRECT("C"&$F22), 4, 0):OFFSET(INDIRECT("C"&$F23), -1, 0)) -> 404.8 | J22: =SUMIF(OFFSET(INDIRECT("B"&$F22), 4, 0):INDIRECT("B"&$F23), "*"&$J$2&"*", OFFSET(INDIRECT("C"&$F22), 4, 0):OFFSET(INDIRECT("C"&$F23), -1, 0)) -> 54.8 | K22: =SUMIF(OFFSET(INDIRECT("B"&$F22), 4, 0):INDIRECT("B"&$F23), "*"&$K$2&"*", OFFSET(INDIRECT("C"&$F22), 4, 0):OFFSET(INDIRECT("C"&$F23), -1, 0)) -> 86.25 | L22: =SUMIF(OFFSET(INDIRECT("B"&$F22), 4, 0):INDIRECT("B"&$F23), "*"&$L$2&"*", OFFSET(INDIRECT("C"&$F22), 4, 0):OFFSET(INDIRECT("C"&$F23), -1, 0)) -> 42.5 | M22: =SUMIF(OFFSET(INDIRECT("B"&$F22), 4, 0):INDIRECT("B"&$F23), "*"&$M$2&"*", OFFSET(INDIRECT("C"&$F22), 4, 0):OFFSET(INDIRECT("C"&$F23), -1, 0)) -> 38.4 | N22: =SUMIF(OFFSET(INDIRECT("B"&$F22), 4, 0):INDIRECT("B"&$F23), "*"&$N$2&"*", OFFSET(INDIRECT("C"&$F22), 4, 0):OFFSET(INDIRECT("C"&$F23), -1, 0)) -> 0 | O22: =SUMIF(OFFSET(INDIRECT("B"&$F22), 4, 0):INDIRECT("B"&$F23), "*"&$O$2&"*", OFFSET(INDIRECT("C"&$F22), 4, 0):OFFSET(INDIRECT("C"&$F23), -1, 0)) -> 0 | P22: =SUMIF(OFFSET(INDIRECT("B"&$F22), 4, 0):INDIRECT("B"&$F23), "*"&$P$2&"*", OFFSET(INDIRECT("C"&$F22), 4, 0):OFFSET(INDIRECT("C"&$F23), -1, 0)) -> 153.4 | Q22: =SUM($I22:$P22) -> 780.15 | S22: N.Ireland | T22: =SUMIF($H$3:$H$120, "I", $K$3:$K$120) -> 0 | W22: DA
A23: =IF(COUNTIF($V$3:$Y$99, $B23)<>0, ROW($B23), 0) -> 23 | B23: KA | F23: {=INDEX(OFFSET(INDIRECT("A"&F22), 1, 0):OFFSET(OFFSET(INDIRECT("A"&F22), 1, 0), 100, 0),MATCH(TRUE,INDEX(OFFSET(INDIRECT("A"&F22), 1, 0):OFFSET(OFFSET(INDIRECT("A"&F22), 1, 0), 100, 0)<>0,),0))} -> 618 | G23: {=INDIRECT("B"&$F23)} -> NW | H23: {=_xlfn.IFS(COUNTIF($V$3:$V$18, G23)<>0, "S", COUNTIF($W$3:$W$99, G23)<>0, "E", COUNTIF($X$3, G23)<>0, "I", COUNTIF($Y$3:$Y$8, G23)<>0, "W")} -> E | I23: =SUMIF(OFFSET(INDIRECT("B"&$F23), 4, 0):INDIRECT("B"&$F24), "*"&$I$2&"*", OFFSET(INDIRECT("C"&$F23), 4, 0):OFFSET(INDIRECT("C"&$F24), -1, 0)) -> 205.2 | J23: =SUMIF(OFFSET(INDIRECT("B"&$F23), 4, 0):INDIRECT("B"&$F24), "*"&$J$2&"*", OFFSET(INDIRECT("C"&$F23), 4, 0):OFFSET(INDIRECT("C"&$F24), -1, 0)) -> 38.4 | K23: =SUMIF(OFFSET(INDIRECT("B"&$F23), 4, 0):INDIRECT("B"&$F24), "*"&$K$2&"*", OFFSET(INDIRECT("C"&$F23), 4, 0):OFFSET(INDIRECT("C"&$F24), -1, 0)) -> 0 | L23: =SUMIF(OFFSET(INDIRECT("B"&$F23), 4, 0):INDIRECT("B"&$F24), "*"&$L$2&"*", OFFSET(INDIRECT("C"&$F23), 4, 0):OFFSET(INDIRECT("C"&$F24), -1, 0)) -> 54.39 | M23: =SUMIF(OFFSET(INDIRECT("B"&$F23), 4, 0):INDIRECT("B"&$F24), "*"&$M$2&"*", OFFSET(INDIRECT("C"&$F23), 4, 0):OFFSET(INDIRECT("C"&$F24), -1, 0)) -> 0 | N23: =SUMIF(OFFSET(INDIRECT("B"&$F23), 4, 0):INDIRECT("B"&$F24), "*"&$N$2&"*", OFFSET(INDIRECT("C"&$F23), 4, 0):OFFSET(INDIRECT("C"&$F24), -1, 0)) -> 28.75 | O23: =SUMIF(OFFSET(INDIRECT("B"&$F23), 4, 0):INDIRECT("B"&$F24), "*"&$O$2&"*", OFFSET(INDIRECT("C"&$F23), 4, 0):OFFSET(INDIRECT("C"&$F24), -1, 0)) -> 0 | P23: =SUMIF(OFFSET(INDIRECT("B"&$F23), 4, 0):INDIRECT("B"&$F24), "*"&$P$2&"*", OFFSET(INDIRECT("C"&$F23), 4, 0):OFFSET(INDIRECT("C"&$F24), -1, 0)) -> 253.55 | Q23: =SUM($I23:$P23) -> 580.29 | S23: Wales | T23: =SUMIF($H$3:$H$120, "W", $K$3:$K$120) -> 169.8 | W23: DE
A24: =IF(COUNTIF($V$3:$Y$99, $B24)<>0, ROW($B24), 0) -> 0 | B24: Total # Sold | C24: 122 | F24: {=INDEX(OFFSET(INDIRECT("A"&F23), 1, 0):OFFSET(OFFSET(INDIRECT("A"&F23), 1, 0), 100, 0),MATCH(TRUE,INDEX(OFFSET(INDIRECT("A"&F23), 1, 0):OFFSET(OFFSET(INDIRECT("A"&F23), 1, 0), 100, 0)<>0,),0))} -> 636 | G24: {=INDIRECT("B"&$F24)} -> BA | H24: {=_xlfn.IFS(COUNTIF($V$3:$V$18, G24)<>0, "S", COUNTIF($W$3:$W$99, G24)<>0, "E", COUNTIF($X$3, G24)<>0, "I", COUNTIF($Y$3:$Y$8, G24)<>0, "W")} -> E | I24: =SUMIF(OFFSET(INDIRECT("B"&$F24), 4, 0):INDIRECT("B"&$F25), "*"&$I$2&"*", OFFSET(INDIRECT("C"&$F24), 4, 0):OFFSET(INDIRECT("C"&$F25), -1, 0)) -> 931.6 | J24: =SUMIF(OFFSET(INDIRECT("B"&$F24), 4, 0):INDIRECT("B"&$F25), "*"&$J$2&"*", OFFSET(INDIRECT("C"&$F24), 4, 0):OFFSET(INDIRECT("C"&$F25), -1, 0)) -> 0 | K24: =SUMIF(OFFSET(INDIRECT("B"&$F24), 4, 0):INDIRECT("B"&$F25), "*"&$K$2&"*", OFFSET(INDIRECT("C"&$F24), 4, 0):OFFSET(INDIRECT("C"&$F25), -1, 0)) -> 0 | L24: =SUMIF(OFFSET(INDIRECT("B"&$F24), 4, 0):INDIRECT("B"&$F25), "*"&$L$2&"*", OFFSET(INDIRECT("C"&$F24), 4, 0):OFFSET(INDIRECT("C"&$F25), -1, 0)) -> 0 | M24: =SUMIF(OFFSET(INDIRECT("B"&$F24), 4, 0):INDIRECT("B"&$F25), "*"&$M$2&"*", OFFSET(INDIRECT("C"&$F24), 4, 0):OFFSET(INDIRECT("C"&$F25), -1, 0)) -> 171.6 | N24: =SUMIF(OFFSET(INDIRECT("B"&$F24), 4, 0):INDIRECT("B"&$F25), "*"&$N$2&"*", OFFSET(INDIRECT("C"&$F24), 4, 0):OFFSET(INDIRECT("C"&$F25), -1, 0)) -> 57.5 | O24: =SUMIF(OFFSET(INDIRECT("B"&$F24), 4, 0):INDIRECT("B"&$F25), "*"&$O$2&"*", OFFSET(INDIRECT("C"&$F24), 4, 0):OFFSET(INDIRECT("C"&$F25), -1, 0)) -> 38.4 | P24: =SUMIF(OFFSET(INDIRECT("B"&$F24), 4, 0):INDIRECT("B"&$F25), "*"&$P$2&"*", OFFSET(INDIRECT("C"&$F24), 4, 0):OFFSET(INDIRECT("C"&$F25), -1, 0)) -> 93.2 | Q24: =SUM($I24:$P24) -> 1292.3 | S24: Total | T24: =SUM(T20:T23) -> 7156.27 | W24: DH
A25: =IF(COUNTIF($V$3:$Y$99, $B25)<>0, ROW($B25), 0) -> 0 | B25: Total Sales | C25: 4727.19 | F25: {=INDEX(OFFSET(INDIRECT("A"&F24), 1, 0):OFFSET(OFFSET(INDIRECT("A"&F24), 1, 0), 100, 0),MATCH(TRUE,INDEX(OFFSET(INDIRECT("A"&F24), 1, 0):OFFSET(OFFSET(INDIRECT("A"&F24), 1, 0), 100, 0)<>0,),0))} -> 657 | G25: {=INDIRECT("B"&$F25)} -> NP | H25: {=_xlfn.IFS(COUNTIF($V$3:$V$18, G25)<>0, "S", COUNTIF($W$3:$W$99, G25)<>0, "E", COUNTIF($X$3, G25)<>0, "I", COUNTIF($Y$3:$Y$8, G25)<>0, "W")} -> W | I25: =SUMIF(OFFSET(INDIRECT("B"&$F25), 4, 0):INDIRECT("B"&$F26), "*"&$I$2&"*", OFFSET(INDIRECT("C"&$F25), 4, 0):OFFSET(INDIRECT("C"&$F26), -1, 0)) -> 2688 | J25: =SUMIF(OFFSET(INDIRECT("B"&$F25), 4, 0):INDIRECT("B"&$F26), "*"&$J$2&"*", OFFSET(INDIRECT("C"&$F25), 4, 0):OFFSET(INDIRECT("C"&$F26), -1, 0)) -> 0 | K25: =SUMIF(OFFSET(INDIRECT("B"&$F25), 4, 0):INDIRECT("B"&$F26), "*"&$K$2&"*", OFFSET(INDIRECT("C"&$F25), 4, 0):OFFSET(INDIRECT("C"&$F26), -1, 0)) -> 0 | L25: =SUMIF(OFFSET(INDIRECT("B"&$F25), 4, 0):INDIRECT("B"&$F26), "*"&$L$2&"*", OFFSET(INDIRECT("C"&$F25), 4, 0):OFFSET(INDIRECT("C"&$F26), -1, 0)) -> 0 | M25: =SUMIF(OFFSET(INDIRECT("B"&$F25), 4, 0):INDIRECT("B"&$F26), "*"&$M$2&"*", OFFSET(INDIRECT("C"&$F25), 4, 0):OFFSET(INDIRECT("C"&$F26), -1, 0)) -> 80 | N25: =SUMIF(OFFSET(INDIRECT("B"&$F25), 4, 0):INDIRECT("B"&$F26), "*"&$N$2&"*", OFFSET(INDIRECT("C"&$F25), 4, 0):OFFSET(INDIRECT("C"&$F26), -1, 0)) -> 28.75 | O25: =SUMIF(OFFSET(INDIRECT("B"&$F25), 4, 0):INDIRECT("B"&$F26), "*"&$O$2&"*", OFFSET(INDIRECT("C"&$F25), 4, 0):OFFSET(INDIRECT("C"&$F26), -1, 0)) -> 38.4 | P25: =SUMIF(OFFSET(INDIRECT("B"&$F25), 4, 0):INDIRECT("B"&$F26), "*"&$P$2&"*", OFFSET(INDIRECT("C"&$F25), 4, 0):OFFSET(INDIRECT("C"&$F26), -1, 0)) -> 189.1 | Q25: =SUM($I25:$P25) -> 3024.25 | W25: DL
A26: =IF(COUNTIF($V$3:$Y$99, $B26)<>0, ROW($B26), 0) -> 0 | B26: Product Name | C26: Sales | D26: Quantity | F26: {=INDEX(OFFSET(INDIRECT("A"&F25), 1, 0):OFFSET(OFFSET(INDIRECT("A"&F25), 1, 0), 100, 0),MATCH(TRUE,INDEX(OFFSET(INDIRECT("A"&F25), 1, 0):OFFSET(OFFSET(INDIRECT("A"&F25), 1, 0), 100, 0)<>0,),0))} -> 676 | G26: {=INDIRECT("B"&$F26)} -> KY | H26: {=_xlfn.IFS(COUNTIF($V$3:$V$18, G26)<>0, "S", COUNTIF($W$3:$W$99, G26)<>0, "E", COUNTIF($X$3, G26)<>0, "I", COUNTIF($Y$3:$Y$8, G26)<>0, "W")} -> S | I26: =SUMIF(OFFSET(INDIRECT("B"&$F26), 4, 0):INDIRECT("B"&$F27), "*"&$I$2&"*", OFFSET(INDIRECT("C"&$F26), 4, 0):OFFSET(INDIRECT("C"&$F27), -1, 0)) -> 1110.7 | J26: =SUMIF(OFFSET(INDIRECT("B"&$F26), 4, 0):INDIRECT("B"&$F27), "*"&$J$2&"*", OFFSET(INDIRECT("C"&$F26), 4, 0):OFFSET(INDIRECT("C"&$F27), -1, 0)) -> 202.32 | K26: =SUMIF(OFFSET(INDIRECT("B"&$F26), 4, 0):INDIRECT("B"&$F27), "*"&$K$2&"*", OFFSET(INDIRECT("C"&$F26), 4, 0):OFFSET(INDIRECT("C"&$F27), -1, 0)) -> 143.95 | L26: =SUMIF(OFFSET(INDIRECT("B"&$F26), 4, 0):INDIRECT("B"&$F27), "*"&$L$2&"*", OFFSET(INDIRECT("C"&$F26), 4, 0):OFFSET(INDIRECT("C"&$F27), -1, 0)) -> 481.49 | M26: =SUMIF(OFFSET(INDIRECT("B"&$F26), 4, 0):INDIRECT("B"&$F27), "*"&$M$2&"*", OFFSET(INDIRECT("C"&$F26), 4, 0):OFFSET(INDIRECT("C"&$F27), -1, 0)) -> 577.6 | N26: =SUMIF(OFFSET(INDIRECT("B"&$F26), 4, 0):INDIRECT("B"&$F27), "*"&$N$2&"*", OFFSET(INDIRECT("C"&$F26), 4, 0):OFFSET(INDIRECT("C"&$F27), -1, 0)) -> 377.89 | O26: =SUMIF(OFFSET(INDIRECT("B"&$F26), 4, 0):INDIRECT("B"&$F27), "*"&$O$2&"*", OFFSET(INDIRECT("C"&$F26), 4, 0):OFFSET(INDIRECT("C"&$F27), -1, 0)) -> 115.2 | P26: =SUMIF(OFFSET(INDIRECT("B"&$F26), 4, 0):INDIRECT("B"&$F27), "*"&$P$2&"*", OFFSET(INDIRECT("C"&$F26), 4, 0):OFFSET(INDIRECT("C"&$F27), -1, 0)) -> 1505.3 | Q26: =SUM($I26:$P26) -> 4514.45 | S26: =L2 -> Elderflower | W26: DN
A27: =IF(COUNTIF($V$3:$Y$99, $B27)<>0, ROW($B27), 0) -> 0 | B27: Thistly Cross Selection Box Gift Box | C27: 595 | D27: 17 | F27: {=INDEX(OFFSET(INDIRECT("A"&F26), 1, 0):OFFSET(OFFSET(INDIRECT("A"&F26), 1, 0), 100, 0),MATCH(TRUE,INDEX(OFFSET(INDIRECT("A"&F26), 1, 0):OFFSET(OFFSET(INDIRECT("A"&F26), 1, 0), 100, 0)<>0,),0))} -> 722 | G27: {=INDIRECT("B"&$F27)} -> PH | H27: {=_xlfn.IFS(COUNTIF($V$3:$V$18, G27)<>0, "S", COUNTIF($W$3:$W$99, G27)<>0, "E", COUNTIF($X$3, G27)<>0, "I", COUNTIF($Y$3:$Y$8, G27)<>0, "W")} -> S | I27: =SUMIF(OFFSET(INDIRECT("B"&$F27), 4, 0):INDIRECT("B"&$F28), "*"&$I$2&"*", OFFSET(INDIRECT("C"&$F27), 4, 0):OFFSET(INDIRECT("C"&$F28), -1, 0)) -> 1267.95 | J27: =SUMIF(OFFSET(INDIRECT("B"&$F27), 4, 0):INDIRECT("B"&$F28), "*"&$J$2&"*", OFFSET(INDIRECT("C"&$F27), 4, 0):OFFSET(INDIRECT("C"&$F28), -1, 0)) -> 78.4 | K27: =SUMIF(OFFSET(INDIRECT("B"&$F27), 4, 0):INDIRECT("B"&$F28), "*"&$K$2&"*", OFFSET(INDIRECT("C"&$F27), 4, 0):OFFSET(INDIRECT("C"&$F28), -1, 0)) -> 155.2 | L27: =SUMIF(OFFSET(INDIRECT("B"&$F27), 4, 0):INDIRECT("B"&$F28), "*"&$L$2&"*", OFFSET(INDIRECT("C"&$F27), 4, 0):OFFSET(INDIRECT("C"&$F28), -1, 0)) -> 432.55 | M27: =SUMIF(OFFSET(INDIRECT("B"&$F27), 4, 0):INDIRECT("B"&$F28), "*"&$M$2&"*", OFFSET(INDIRECT("C"&$F27), 4, 0):OFFSET(INDIRECT("C"&$F28), -1, 0)) -> 412.8 | N27: =SUMIF(OFFSET(INDIRECT("B"&$F27), 4, 0):INDIRECT("B"&$F28), "*"&$N$2&"*", OFFSET(INDIRECT("C"&$F27), 4, 0):OFFSET(INDIRECT("C"&$F28), -1, 0)) -> 92.06 | O27: =SUMIF(OFFSET(INDIRECT("B"&$F27), 4, 0):INDIRECT("B"&$F28), "*"&$O$2&"*", OFFSET(INDIRECT("C"&$F27), 4, 0):OFFSET(INDIRECT("C"&$F28), -1, 0)) -> 116.8 | P27: =SUMIF(OFFSET(INDIRECT("B"&$F27), 4, 0):INDIRECT("B"&$F28), "*"&$P$2&"*", OFFSET(INDIRECT("C"&$F27), 4, 0):OFFSET(INDIRECT("C"&$F28), -1, 0)) -> 883.05 | Q27: =SUM($I27:$P27) -> 3438.81 | S27: Region | T27: Sales | W27: DT
A28: =IF(COUNTIF($V$3:$Y$99, $B28)<>0, ROW($B28), 0) -> 0 | B28: Mix & Match 500ml Bottle Case (24 bottles) | C28: 383.6 | D28: 7 | F28: {=INDEX(OFFSET(INDIRECT("A"&F27), 1, 0):OFFSET(OFFSET(INDIRECT("A"&F27), 1, 0), 100, 0),MATCH(TRUE,INDEX(OFFSET(INDIRECT("A"&F27), 1, 0):OFFSET(OFFSET(INDIRECT("A"&F27), 1, 0), 100, 0)<>0,),0))} -> 760 | G28: {=INDIRECT("B"&$F28)} -> SP | H28: {=_xlfn.IFS(COUNTIF($V$3:$V$18, G28)<>0, "S", COUNTIF($W$3:$W$99, G28)<>0, "E", COUNTIF($X$3, G28)<>0, "I", COUNTIF($Y$3:$Y$8, G28)<>0, "W")} -> E | I28: =SUMIF(OFFSET(INDIRECT("B"&$F28), 4, 0):INDIRECT("B"&$F29), "*"&$I$2&"*", OFFSET(INDIRECT("C"&$F28), 4, 0):OFFSET(INDIRECT("C"&$F29), -1, 0)) -> 516 | J28: =SUMIF(OFFSET(INDIRECT("B"&$F28), 4, 0):INDIRECT("B"&$F29), "*"&$J$2&"*", OFFSET(INDIRECT("C"&$F28), 4, 0):OFFSET(INDIRECT("C"&$F29), -1, 0)) -> 0 | K28: =SUMIF(OFFSET(INDIRECT("B"&$F28), 4, 0):INDIRECT("B"&$F29), "*"&$K$2&"*", OFFSET(INDIRECT("C"&$F28), 4, 0):OFFSET(INDIRECT("C"&$F29), -1, 0)) -> 28.75 | L28: =SUMIF(OFFSET(INDIRECT("B"&$F28), 4, 0):INDIRECT("B"&$F29), "*"&$L$2&"*", OFFSET(INDIRECT("C"&$F28), 4, 0):OFFSET(INDIRECT("C"&$F29), -1, 0)) -> 0 | M28: =SUMIF(OFFSET(INDIRECT("B"&$F28), 4, 0):INDIRECT("B"&$F29), "*"&$M$2&"*", OFFSET(INDIRECT("C"&$F28), 4, 0):OFFSET(INDIRECT("C"&$F29), -1, 0)) -> 64 | N28: =SUMIF(OFFSET(INDIRECT("B"&$F28), 4, 0):INDIRECT("B"&$F29), "*"&$N$2&"*", OFFSET(INDIRECT("C"&$F28), 4, 0):OFFSET(INDIRECT("C"&$F29), -1, 0)) -> 0 | O28: =SUMIF(OFFSET(INDIRECT("B"&$F28), 4, 0):INDIRECT("B"&$F29), "*"&$O$2&"*", OFFSET(INDIRECT("C"&$F28), 4, 0):OFFSET(INDIRECT("C"&$F29), -1, 0)) -> 0 | P28: =SUMIF(OFFSET(INDIRECT("B"&$F28), 4, 0):INDIRECT("B"&$F29), "*"&$P$2&"*", OFFSET(INDIRECT("C"&$F28), 4, 0):OFFSET(INDIRECT("C"&$F29), -1, 0)) -> 167.1 | Q28: =SUM($I28:$P28) -> 775.85 | S28: England | T28: =SUMIF($H$3:$H$120, "E", $L$3:$L$120) -> 9759.9 | W28: DY
A29: =IF(COUNTIF($V$3:$Y$99, $B29)<>0, ROW($B29), 0) -> 0 | B29: Traditional - 2x5L Ciderbox 2 x 5L Ciderbox | C29: 80 | D29: 2 | F29: {=INDEX(OFFSET(INDIRECT("A"&F28), 1, 0):OFFSET(OFFSET(INDIRECT("A"&F28), 1, 0), 100, 0),MATCH(TRUE,INDEX(OFFSET(INDIRECT("A"&F28), 1, 0):OFFSET(OFFSET(INDIRECT("A"&F28), 1, 0), 100, 0)<>0,),0))} -> 776 | G29: {=INDIRECT("B"&$F29)} -> FK | H29: {=_xlfn.IFS(COUNTIF($V$3:$V$18, G29)<>0, "S", COUNTIF($W$3:$W$99, G29)<>0, "E", COUNTIF($X$3, G29)<>0, "I", COUNTIF($Y$3:$Y$8, G29)<>0, "W")} -> S | I29: =SUMIF(OFFSET(INDIRECT("B"&$F29), 4, 0):INDIRECT("B"&$F30), "*"&$I$2&"*", OFFSET(INDIRECT("C"&$F29), 4, 0):OFFSET(INDIRECT("C"&$F30), -1, 0)) -> 974.7 | J29: =SUMIF(OFFSET(INDIRECT("B"&$F29), 4, 0):INDIRECT("B"&$F30), "*"&$J$2&"*", OFFSET(INDIRECT("C"&$F29), 4, 0):OFFSET(INDIRECT("C"&$F30), -1, 0)) -> 478.4 | K29: =SUMIF(OFFSET(INDIRECT("B"&$F29), 4, 0):INDIRECT("B"&$F30), "*"&$K$2&"*", OFFSET(INDIRECT("C"&$F29), 4, 0):OFFSET(INDIRECT("C"&$F30), -1, 0)) -> 93.2 | L29: =SUMIF(OFFSET(INDIRECT("B"&$F29), 4, 0):INDIRECT("B"&$F30), "*"&$L$2&"*", OFFSET(INDIRECT("C"&$F29), 4, 0):OFFSET(INDIRECT("C"&$F30), -1, 0)) -> 233.1 | M29: =SUMIF(OFFSET(INDIRECT("B"&$F29), 4, 0):INDIRECT("B"&$F30), "*"&$M$2&"*", OFFSET(INDIRECT("C"&$F29), 4, 0):OFFSET(INDIRECT("C"&$F30), -1, 0)) -> 429.2 | N29: =SUMIF(OFFSET(INDIRECT("B"&$F29), 4, 0):INDIRECT("B"&$F30), "*"&$N$2&"*", OFFSET(INDIRECT("C"&$F29), 4, 0):OFFSET(INDIRECT("C"&$F30), -1, 0)) -> 0 | O29: =SUMIF(OFFSET(INDIRECT("B"&$F29), 4, 0):INDIRECT("B"&$F30), "*"&$O$2&"*", OFFSET(INDIRECT("C"&$F29), 4, 0):OFFSET(INDIRECT("C"&$F30), -1, 0)) -> 0 | P29: =SUMIF(OFFSET(INDIRECT("B"&$F29), 4, 0):INDIRECT("B"&$F30), "*"&$P$2&"*", OFFSET(INDIRECT("C"&$F29), 4, 0):OFFSET(INDIRECT("C"&$F30), -1, 0)) -> 1209.8 | Q29: =SUM($I29:$P29) -> 3418.4 | S29: Scotland | T29: =SUMIF($H$3:$H$120, "S", $L$3:$L$120) -> 7778.64 | W29: EC
A30: =IF(COUNTIF($V$3:$Y$99, $B30)<>0, ROW($B30), 0) -> 0 | B30: Whisky Cask - Bottle 24 x 330ml | C30: 230.4 | D30: 7 | F30: {=INDEX(OFFSET(INDIRECT("A"&F29), 1, 0):OFFSET(OFFSET(INDIRECT("A"&F29), 1, 0), 100, 0),MATCH(TRUE,INDEX(OFFSET(INDIRECT("A"&F29), 1, 0):OFFSET(OFFSET(INDIRECT("A"&F29), 1, 0), 100, 0)<>0,),0))} -> 810 | G30: {=INDIRECT("B"&$F30)} -> DG | H30: {=_xlfn.IFS(COUNTIF($V$3:$V$18, G30)<>0, "S", COUNTIF($W$3:$W$99, G30)<>0, "E", COUNTIF($X$3, G30)<>0, "I", COUNTIF($Y$3:$Y$8, G30)<>0, "W")} -> S | I30: =SUMIF(OFFSET(INDIRECT("B"&$F30), 4, 0):INDIRECT("B"&$F31), "*"&$I$2&"*", OFFSET(INDIRECT("C"&$F30), 4, 0):OFFSET(INDIRECT("C"&$F31), -1, 0)) -> 1182.7 | J30: =SUMIF(OFFSET(INDIRECT("B"&$F30), 4, 0):INDIRECT("B"&$F31), "*"&$J$2&"*", OFFSET(INDIRECT("C"&$F30), 4, 0):OFFSET(INDIRECT("C"&$F31), -1, 0)) -> 285.2 | K30: =SUMIF(OFFSET(INDIRECT("B"&$F30), 4, 0):INDIRECT("B"&$F31), "*"&$K$2&"*", OFFSET(INDIRECT("C"&$F30), 4, 0):OFFSET(INDIRECT("C"&$F31), -1, 0)) -> 38.4 | L30: =SUMIF(OFFSET(INDIRECT("B"&$F30), 4, 0):INDIRECT("B"&$F31), "*"&$L$2&"*", OFFSET(INDIRECT("C"&$F30), 4, 0):OFFSET(INDIRECT("C"&$F31), -1, 0)) -> 99.9 | M30: =SUMIF(OFFSET(INDIRECT("B"&$F30), 4, 0):INDIRECT("B"&$F31), "*"&$M$2&"*", OFFSET(INDIRECT("C"&$F30), 4, 0):OFFSET(INDIRECT("C"&$F31), -1, 0)) -> 131.6 | N30: =SUMIF(OFFSET(INDIRECT("B"&$F30), 4, 0):INDIRECT("B"&$F31), "*"&$N$2&"*", OFFSET(INDIRECT("C"&$F30), 4, 0):OFFSET(INDIRECT("C"&$F31), -1, 0)) -> 168.86 | O30: =SUMIF(OFFSET(INDIRECT("B"&$F30), 4, 0):INDIRECT("B"&$F31), "*"&$O$2&"*", OFFSET(INDIRECT("C"&$F30), 4, 0):OFFSET(INDIRECT("C"&$F31), -1, 0)) -> 256 | P30: =SUMIF(OFFSET(INDIRECT("B"&$F30), 4, 0):INDIRECT("B"&$F31), "*"&$P$2&"*", OFFSET(INDIRECT("C"&$F30), 4, 0):OFFSET(INDIRECT("C"&$F31), -1, 0)) -> 2151.15 | Q30: =SUM($I30:$P30) -> 4313.81 | S30: N.Ireland | T30: =SUMIF($H$3:$H$120, "I", $L$3:$L$120) -> 109.19 | W30: EN
A31: =IF(COUNTIF($V$3:$Y$99, $B31)<>0, ROW($B31), 0) -> 0 | B31: Strawberry - Bottle 24 x 500ml | C31: 219.2 | D31: 4 | F31: {=INDEX(OFFSET(INDIRECT("A"&F30), 1, 0):OFFSET(OFFSET(INDIRECT("A"&F30), 1, 0), 100, 0),MATCH(TRUE,INDEX(OFFSET(INDIRECT("A"&F30), 1, 0):OFFSET(OFFSET(INDIRECT("A"&F30), 1, 0), 100, 0)<>0,),0))} -> 845 | G31: {=INDIRECT("B"&$F31)} -> TA | H31: {=_xlfn.IFS(COUNTIF($V$3:$V$18, G31)<>0, "S", COUNTIF($W$3:$W$99, G31)<>0, "E", COUNTIF($X$3, G31)<>0, "I", COUNTIF($Y$3:$Y$8, G31)<>0, "W")} -> E | I31: =SUMIF(OFFSET(INDIRECT("B"&$F31), 4, 0):INDIRECT("B"&$F32), "*"&$I$2&"*", OFFSET(INDIRECT("C"&$F31), 4, 0):OFFSET(INDIRECT("C"&$F32), -1, 0)) -> 790.8 | J31: =SUMIF(OFFSET(INDIRECT("B"&$F31), 4, 0):INDIRECT("B"&$F32), "*"&$J$2&"*", OFFSET(INDIRECT("C"&$F31), 4, 0):OFFSET(INDIRECT("C"&$F32), -1, 0)) -> 0 | K31: =SUMIF(OFFSET(INDIRECT("B"&$F31), 4, 0):INDIRECT("B"&$F32), "*"&$K$2&"*", OFFSET(INDIRECT("C"&$F31), 4, 0):OFFSET(INDIRECT("C"&$F32), -1, 0)) -> 0 | L31: =SUMIF(OFFSET(INDIRECT("B"&$F31), 4, 0):INDIRECT("B"&$F32), "*"&$L$2&"*", OFFSET(INDIRECT("C"&$F31), 4, 0):OFFSET(INDIRECT("C"&$F32), -1, 0)) -> 109.6 | M31: =SUMIF(OFFSET(INDIRECT("B"&$F31), 4, 0):INDIRECT("B"&$F32), "*"&$M$2&"*", OFFSET(INDIRECT("C"&$F31), 4, 0):OFFSET(INDIRECT("C"&$F32), -1, 0)) -> 0 | N31: =SUMIF(OFFSET(INDIRECT("B"&$F31), 4, 0):INDIRECT("B"&$F32), "*"&$N$2&"*", OFFSET(INDIRECT("C"&$F31), 4, 0):OFFSET(INDIRECT("C"&$F32), -1, 0)) -> 0 | O31: =SUMIF(OFFSET(INDIRECT("B"&$F31), 4, 0):INDIRECT("B"&$F32), "*"&$O$2&"*", OFFSET(INDIRECT("C"&$F31), 4, 0):OFFSET(INDIRECT("C"&$F32), -1, 0)) -> 0 | P31: =SUMIF(OFFSET(INDIRECT("B"&$F31), 4, 0):INDIRECT("B"&$F32), "*"&$P$2&"*", OFFSET(INDIRECT("C"&$F31), 4, 0):OFFSET(INDIRECT("C"&$F32), -1, 0)) -> 220.75 | Q31: =SUM($I31:$P31) -> 1121.15 | S31: Wales | T31: =SUMIF($H$3:$H$120, "W", $L$3:$L$120) -> 582.33 | W31: EX
A32: =IF(COUNTIF($V$3:$Y$99, $B32)<>0, ROW($B32), 0) -> 0 | B32: Mull at Home Cider Kit | C32: 75 | D32: 2 | F32: {=INDEX(OFFSET(INDIRECT("A"&F31), 1, 0):OFFSET(OFFSET(INDIRECT("A"&F31), 1, 0), 100, 0),MATCH(TRUE,INDEX(OFFSET(INDIRECT("A"&F31), 1, 0):OFFSET(OFFSET(INDIRECT("A"&F31), 1, 0), 100, 0)<>0,),0))} -> 860 | G32: {=INDIRECT("B"&$F32)} -> BS | H32: {=_xlfn.IFS(COUNTIF($V$3:$V$18, G32)<>0, "S", COUNTIF($W$3:$W$99, G32)<>0, "E", COUNTIF($X$3, G32)<>0, "I", COUNTIF($Y$3:$Y$8, G32)<>0, "W")} -> E | I32: =SUMIF(OFFSET(INDIRECT("B"&$F32), 4, 0):INDIRECT("B"&$F33), "*"&$I$2&"*", OFFSET(INDIRECT("C"&$F32), 4, 0):OFFSET(INDIRECT("C"&$F33), -1, 0)) -> 2472 | J32: =SUMIF(OFFSET(INDIRECT("B"&$F32), 4, 0):INDIRECT("B"&$F33), "*"&$J$2&"*", OFFSET(INDIRECT("C"&$F32), 4, 0):OFFSET(INDIRECT("C"&$F33), -1, 0)) -> 54.8 | K32: =SUMIF(OFFSET(INDIRECT("B"&$F32), 4, 0):INDIRECT("B"&$F33), "*"&$K$2&"*", OFFSET(INDIRECT("C"&$F32), 4, 0):OFFSET(INDIRECT("C"&$F33), -1, 0)) -> 0 | L32: =SUMIF(OFFSET(INDIRECT("B"&$F32), 4, 0):INDIRECT("B"&$F33), "*"&$L$2&"*", OFFSET(INDIRECT("C"&$F32), 4, 0):OFFSET(INDIRECT("C"&$F33), -1, 0)) -> 170 | M32: =SUMIF(OFFSET(INDIRECT("B"&$F32), 4, 0):INDIRECT("B"&$F33), "*"&$M$2&"*", OFFSET(INDIRECT("C"&$F32), 4, 0):OFFSET(INDIRECT("C"&$F33), -1, 0)) -> 94.8 | N32: =SUMIF(OFFSET(INDIRECT("B"&$F32), 4, 0):INDIRECT("B"&$F33), "*"&$N$2&"*", OFFSET(INDIRECT("C"&$F32), 4, 0):OFFSET(INDIRECT("C"&$F33), -1, 0)) -> 67.15 | O32: =SUMIF(OFFSET(INDIRECT("B"&$F32), 4, 0):INDIRECT("B"&$F33), "*"&$O$2&"*", OFFSET(INDIRECT("C"&$F32), 4, 0):OFFSET(INDIRECT("C"&$F33), -1, 0)) -> 156.8 | P32: =SUMIF(OFFSET(INDIRECT("B"&$F32), 4, 0):INDIRECT("B"&$F33), "*"&$P$2&"*", OFFSET(INDIRECT("C"&$F32), 4, 0):OFFSET(INDIRECT("C"&$F33), -1, 0)) -> 723.8 | Q32: =SUM($I32:$P32) -> 3739.35 | S32: Total | T32: =SUM(T28:T31) -> 18230.06 | W32: FY
